Workbook

Sheet README
A1: Kastel Fortune — mathematical model (Excel edition)
A3: Original 5x3, 20-payline slot with free spins (multiplier ladder x1→x5, retriggers), max win 1,500x. Companion to the Python repository slot-math-portfolio.
A5: LEGEND: blue text = hard-coded input you may edit · black = formula · green = link to another sheet · grey fill = reference value computed in Python (full enumeration) · yellow = key output.
A7: WHAT IS EXACT IN THIS WORKBOOK (pure formulas):
A8: • Reel-strip counts and per-reel symbol probabilities (COUNTIF / COUNTA) — sheets Reels_Base, Reels_FS.
A9: • Single-line expected value, closed form P(run>=k) = p1(s)·Π(p_i(s)+p_i(W)) — exact because reel 1 carries no wild — sheets Lines_Base, Lines_FS.
A10: • Scatter-count distribution (Poisson-binomial dynamic programme) — sheet Scatters.
A11: • Free-spins expected payout: the absorbing Markov chain's mean recursion over states (spins left, multiplier, retriggers) — sheet FreeSpins.
A12: • RTP = 20 × E[line] + scatter pays + Σ P(k scatters) × E[feature | k] — sheet Dashboard; the Python exact value is shown next to it with the difference (should be 0).
A14: WHAT NEEDS THE FULL ENUMERATION (Python, shown as grey reference values): hit frequency, variance / volatility, tail probabilities, max-win reachability, cap cost.
A15: Those depend on the joint law of 20 overlapping lines and are obtained by enumerating all 55,520,640 stop combinations (slotmath/exact.py).
A17: INPUTS TAKEN FROM PYTHON (sheet FreeSpins, blue): the four per-free-spin outcome-class probabilities and two class means, from the enumeration of the free-spin strips. Two cross-checks on that sheet recompute what can be recomputed here (retrigger probability, E[line win per free spin]) and must read OK.
... A21: ASSUMPTIONS: reels stop uniformly and independently; lines pay left to right, best win per line; scatters pay anywhere and do not pay inside free spins; the multiplier climbs after a winning free spin and applies to the following spins; the max-win cap truncates the total win of a spin including its feature.

Sheet Dashboard
A1: Kastel Fortune — math model dashboard
A2: Green = linked from model sheets, black = formula, grey = reference values from the full enumeration in Python (not computable in Excel).
A4: RTP decomposition | B4: Excel (live) | C4: Python exact | D4: Difference
A5: Line RTP = paylines x E[one line] | B5: =Paytable!$B$27*Lines_Base!$V$14 -> 0.58705051 | C5: 0.58705051 | D5: =B5-C5 -> 0
A6: Scatter-pay RTP | B6: =Scatters!$E$20 -> 0.012790811 | C6: 0.012790811 | D6: =B6-C6 -> 0
A7: Free-spins RTP | B7: =FreeSpins!$E$60 -> 0.36218116 | C7: 0.36218116 | D7: =B7-C7 -> 0
A8: TOTAL RTP (uncapped) | B8: =SUM(B5:B7) -> 0.96202248 | C8: 0.96202248 | D8: =B8-C8 -> 0
A9: Max-win cap cost (needs the full distribution) | C9: 2.1136337e-07
A10: RTP with cap (exact) | C10: 0.96202227
A12: Frequencies | B12: Excel (live) | C12: Python exact | D12: Difference
A13: P(one line pays) | B13: =Lines_Base!$W$14 -> 0.029749657
A14: Free-spins trigger probability | B14: =Scatters!$B$19 -> 0.0053449852 | C14: 0.0053449852 | D14: =B14-C14 -> 0
A15: ... one feature every N spins | B15: =1/B14 -> 187.09126
A16: E[feature payout | 3 scatters] (x bet) | B16: =FreeSpins!$C$57 -> 65.404958 | C16: 65.404958 | D16: =B16-C16 -> 0
A17: E[feature payout | 4 scatters] (x bet) | B17: =FreeSpins!$C$58 -> 116.76056 | C17: 116.76056 | D17: =B17-C17 -> 0
A18: E[feature payout | 5 scatters] (x bet) | B18: =FreeSpins!$C$59 -> 169.36527 | C18: 169.36527 | D18: =B18-C18 -> 0
A19: Closed-form validity (no wild on reel 1) | B19: =Lines_Base!$V$15 -> OK
A21: Needs the full grid enumeration (Python) | C21: Python exact
A22: Hit frequency (any win > 0) | C22: 0.34810941
A23: Std dev of win per spin (x bet) | C23: 7.551762
A24: Volatility index 1.96 x sigma | C24: 14.801454
A25: E[feature | triggered] (x bet) | C25: 67.76089
A26: Median feature payout (x bet) | C26: 47.8
A27: P(win >= 100x) 1 in | C27: 913.86136
A28: P(win >= 1000x) 1 in | C28: 4319605.8
A29: P(max win 1,500x) 1 in | C29: 5.1563618e+08
A30: Base-game stop combinations enumerated | C30: 55520640
A31: Free-spin stop combinations enumerated | C31: 12644352
A33: Monte-Carlo check: 100,000,000 spins (seed 2024): RTP 96.1923% +/- 0.1480 pp (95% CI), hit 34.815%, sigma 7.5503 — exact value inside the interval (z = -0.13).

Sheet Paytable
A1: Kastel Fortune — paytable and game parameters
A2: Pays in multiples of the TOTAL bet. Blue = input. Line pays left to right from reel 1; wild substitutes for all but the scatter.
A4: Symbol | B4: Name | C4: 3 of a kind | D4: 4 of a kind | E4: 5 of a kind
A5: W | B5: Wild (zlatni ključ) | C5: 0 | D5: 0 | E5: 0
A6: S | B6: Scatter (grb grada) | C6: 0 | D6: 0 | E6: 0
A7: H1 | B7: Kastel (tvrđava) | C7: 2 | D7: 8 | E7: 40
A8: H2 | B8: Vrbas | C8: 1.5 | D8: 5 | E8: 25
A9: H3 | B9: Dajak čamac | C9: 1 | D9: 3 | E9: 15
A10: H4 | B10: Lipa | C10: 0.8 | D10: 2 | E10: 10
A11: A | B11: A | C11: 0.4 | D11: 1.2 | E11: 5
A12: K | B12: K | C12: 0.3 | D12: 1 | E12: 4
A13: Q | B13: Q | C13: 0.3 | D13: 0.8 | E13: 3
A14: J | B14: J | C14: 0.2 | D14: 0.6 | E14: 2.5
A17: Scatter pays (anywhere on the grid)
A18: Scatters | B18: Pay (x bet) | C18: Free spins awarded
A19: 3 | B19: 2 | C19: 10
A20: 4 | B20: 10 | C20: 15
A21: 5 | B21: 50 | C21: 20
A24: Game parameters
A25: Reels | B25: 5
A26: Rows | B26: 3
A27: Paylines | B27: 20
A28: Max win cap (x bet) | B28: 1500
A29: Retrigger: scatters needed | B29: 3
A30: Retrigger: extra spins | B30: 5
A31: Max retriggers | B31: 4
A32: Multiplier start | B32: 1
A33: Multiplier step per winning spin | B33: 1
A34: Multiplier cap | B34: 5

Sheet Reels_Base
A1: Kastel Fortune — base-game reel strips
A2: Strips top-to-bottom (wrapping). Blue cells are inputs: edit a symbol and every probability, the line EV and the RTP recalculate.
I3: Symbol counts per reel (COUNTIF) | P3: P(symbol on a given row of the reel) = count / length
A4: Pos | B4: Reel 1 | C4: Reel 2 | D4: Reel 3 | E4: Reel 4 | F4: Reel 5 | I4: Symbol | J4: Reel 1 | K4: Reel 2 | L4: Reel 3 | M4: Reel 4 | N4: Reel 5 | P4: Symbol | Q4: Reel 1 | R4: Reel 2 | S4: Reel 3 | T4: Reel 4 | U4: Reel 5
A5: 1 | B5: A | C5: A | D5: A | E5: H4 | F5: A | I5: W | J5: =COUNTIF(B$5:B$54,$I5) -> 0 | K5: =COUNTIF(C$5:C$54,$I5) -> 2 | L5: =COUNTIF(D$5:D$54,$I5) -> 2 | M5: =COUNTIF(E$5:E$54,$I5) -> 2 | N5: =COUNTIF(F$5:F$54,$I5) -> 0 | P5: W | Q5: =J5/J$15 -> 0 | R5: =K5/K$15 -> 0.055555556 | S5: =L5/L$15 -> 0.055555556 | T5: =M5/M$15 -> 0.057142857 | U5: =N5/N$15 -> 0
A6: 2 | B6: K | C6: K | D6: K | E6: A | F6: H1 | I6: S | J6: =COUNTIF(B$5:B$54,$I6) -> 1 | K6: =COUNTIF(C$5:C$54,$I6) -> 1 | L6: =COUNTIF(D$5:D$54,$I6) -> 1 | M6: =COUNTIF(E$5:E$54,$I6) -> 1 | N6: =COUNTIF(F$5:F$54,$I6) -> 1 | P6: S | Q6: =J6/J$15 -> 0.027777778 | R6: =K6/K$15 -> 0.027777778 | S6: =L6/L$15 -> 0.027777778 | T6: =M6/M$15 -> 0.028571429 | U6: =N6/N$15 -> 0.029411765
A7: 3 | B7: Q | C7: Q | D7: Q | E7: Q | F7: H2 | I7: H1 | J7: =COUNTIF(B$5:B$54,$I7) -> 3 | K7: =COUNTIF(C$5:C$54,$I7) -> 4 | L7: =COUNTIF(D$5:D$54,$I7) -> 4 | M7: =COUNTIF(E$5:E$54,$I7) -> 4 | N7: =COUNTIF(F$5:F$54,$I7) -> 3 | P7: H1 | Q7: =J7/J$15 -> 0.083333333 | R7: =K7/K$15 -> 0.11111111 | S7: =L7/L$15 -> 0.11111111 | T7: =M7/M$15 -> 0.11428571 | U7: =N7/N$15 -> 0.088235294
A8: 4 | B8: J | C8: J | D8: J | E8: K | F8: J | I8: H2 | J8: =COUNTIF(B$5:B$54,$I8) -> 4 | K8: =COUNTIF(C$5:C$54,$I8) -> 4 | L8: =COUNTIF(D$5:D$54,$I8) -> 3 | M8: =COUNTIF(E$5:E$54,$I8) -> 2 | N8: =COUNTIF(F$5:F$54,$I8) -> 5 | P8: H2 | Q8: =J8/J$15 -> 0.11111111 | R8: =K8/K$15 -> 0.11111111 | S8: =L8/L$15 -> 0.083333333 | T8: =M8/M$15 -> 0.057142857 | U8: =N8/N$15 -> 0.14705882
A9: 5 | B9: H2 | C9: H2 | D9: S | E9: H3 | F9: H3 | I9: H3 | J9: =COUNTIF(B$5:B$54,$I9) -> 4 | K9: =COUNTIF(C$5:C$54,$I9) -> 3 | L9: =COUNTIF(D$5:D$54,$I9) -> 3 | M9: =COUNTIF(E$5:E$54,$I9) -> 2 | N9: =COUNTIF(F$5:F$54,$I9) -> 4 | P9: H3 | Q9: =J9/J$15 -> 0.11111111 | R9: =K9/K$15 -> 0.083333333 | S9: =L9/L$15 -> 0.083333333 | T9: =M9/M$15 -> 0.057142857 | U9: =N9/N$15 -> 0.11764706
A10: 6 | B10: H3 | C10: S | D10: H2 | E10: H1 | F10: A | I10: H4 | J10: =COUNTIF(B$5:B$54,$I10) -> 4 | K10: =COUNTIF(C$5:C$54,$I10) -> 2 | L10: =COUNTIF(D$5:D$54,$I10) -> 3 | M10: =COUNTIF(E$5:E$54,$I10) -> 5 | N10: =COUNTIF(F$5:F$54,$I10) -> 4 | P10: H4 | Q10: =J10/J$15 -> 0.11111111 | R10: =K10/K$15 -> 0.055555556 | S10: =L10/L$15 -> 0.083333333 | T10: =M10/M$15 -> 0.14285714 | U10: =N10/N$15 -> 0.11764706
A11: 7 | B11: H4 | C11: H4 | D11: H1 | E11: A | F11: H4 | I11: A | J11: =COUNTIF(B$5:B$54,$I11) -> 5 | K11: =COUNTIF(C$5:C$54,$I11) -> 5 | L11: =COUNTIF(D$5:D$54,$I11) -> 5 | M11: =COUNTIF(E$5:E$54,$I11) -> 7 | N11: =COUNTIF(F$5:F$54,$I11) -> 6 | P11: A | Q11: =J11/J$15 -> 0.13888889 | R11: =K11/K$15 -> 0.13888889 | S11: =L11/L$15 -> 0.13888889 | T11: =M11/M$15 -> 0.2 | U11: =N11/N$15 -> 0.17647059
A12: 8 | B12: A | C12: A | D12: A | E12: J | F12: K | I12: K | J12: =COUNTIF(B$5:B$54,$I12) -> 5 | K12: =COUNTIF(C$5:C$54,$I12) -> 5 | L12: =COUNTIF(D$5:D$54,$I12) -> 5 | M12: =COUNTIF(E$5:E$54,$I12) -> 3 | N12: =COUNTIF(F$5:F$54,$I12) -> 4 | P12: K | Q12: =J12/J$15 -> 0.13888889 | R12: =K12/K$15 -> 0.13888889 | S12: =L12/L$15 -> 0.13888889 | T12: =M12/M$15 -> 0.085714286 | U12: =N12/N$15 -> 0.11764706
A13: 9 | B13: K | C13: K | D13: K | E13: H4 | F13: H2 | I13: Q | J13: =COUNTIF(B$5:B$54,$I13) -> 5 | K13: =COUNTIF(C$5:C$54,$I13) -> 5 | L13: =COUNTIF(D$5:D$54,$I13) -> 5 | M13: =COUNTIF(E$5:E$54,$I13) -> 5 | N13: =COUNTIF(F$5:F$54,$I13) -> 4 | P13: Q | Q13: =J13/J$15 -> 0.13888889 | R13: =K13/K$15 -> 0.13888889 | S13: =L13/L$15 -> 0.13888889 | T13: =M13/M$15 -> 0.14285714 | U13: =N13/N$15 -> 0.11764706
A14: 10 | B14: Q | C14: Q | D14: Q | E14: Q | F14: Q | I14: J | J14: =COUNTIF(B$5:B$54,$I14) -> 5 | K14: =COUNTIF(C$5:C$54,$I14) -> 5 | L14: =COUNTIF(D$5:D$54,$I14) -> 5 | M14: =COUNTIF(E$5:E$54,$I14) -> 4 | N14: =COUNTIF(F$5:F$54,$I14) -> 3 | P14: J | Q14: =J14/J$15 -> 0.13888889 | R14: =K14/K$15 -> 0.13888889 | S14: =L14/L$15 -> 0.13888889 | T14: =M14/M$15 -> 0.11428571 | U14: =N14/N$15 -> 0.088235294
A15: 11 | B15: J | C15: J | D15: J | E15: H2 | F15: H1 | I15: Strip length | J15: =COUNTA(B$5:B$54) -> 36 | K15: =COUNTA(C$5:C$54) -> 36 | L15: =COUNTA(D$5:D$54) -> 36 | M15: =COUNTA(E$5:E$54) -> 35 | N15: =COUNTA(F$5:F$54) -> 34 | P15: check: sums to 1 | Q15: =SUM(Q5:Q14) -> 1 | R15: =SUM(R5:R14) -> 1 | S15: =SUM(S5:S14) -> 1 | T15: =SUM(T5:T14) -> 1 | U15: =SUM(U5:U14) -> 1
A16: 12 | B16: H1 | C16: H1 | D16: H3 | E16: A | F16: A
A17: 13 | B17: H2 | C17: H2 | D17: H4 | E17: W | F17: J
A18: 14 | B18: H3 | C18: H3 | D18: W | E18: J | F18: H3
A19: 15 | B19: A | C19: A | D19: A | E19: H4 | F19: H4
A20: 16 | B20: K | C20: K | D20: K | E20: Q | F20: H2
A21: 17 | B21: Q | C21: Q | D21: Q | E21: A | F21: K
A22: 18 | B22: J | C22: J | D22: J | E22: H1 | F22: A
A23: 19 | B23: H4 | C23: W | D23: H1 | E23: K | F23: Q
A24: 20 | B24: H1 | C24: H1 | D24: H2 | E24: S | F24: S
A25: 21 | B25: H2 | C25: H2 | D25: H3 | E25: H3 | F25: H3
A26: 22 | B26: H3 | C26: A | D26: A | E26: A | F26: H2
A27: 23 | B27: A | C27: K | D27: K | E27: H4 | F27: A
... A38: 34 | B38: H3 | C38: W | D38: H3 | E38: H2 | F38: Q
A39: 35 | B39: H4 | C39: H3 | D39: H1 | E39: J
A40: 36 | B40: H1 | C40: H1 | D40: H4
A41: 37
A42: 38
A43: 39
A44: 40
A45: 41
A46: 42
A47: 43
A48: 44
A49: 45
A50: 46
...

Sheet Reels_FS
A1: Kastel Fortune — free-spins reel strips
A2: Strips top-to-bottom (wrapping). Blue cells are inputs: edit a symbol and every probability, the line EV and the RTP recalculate.
I3: Symbol counts per reel (COUNTIF) | P3: P(symbol on a given row of the reel) = count / length
A4: Pos | B4: Reel 1 | C4: Reel 2 | D4: Reel 3 | E4: Reel 4 | F4: Reel 5 | I4: Symbol | J4: Reel 1 | K4: Reel 2 | L4: Reel 3 | M4: Reel 4 | N4: Reel 5 | P4: Symbol | Q4: Reel 1 | R4: Reel 2 | S4: Reel 3 | T4: Reel 4 | U4: Reel 5
A5: 1 | B5: H1 | C5: W | D5: W | E5: W | F5: A | I5: W | J5: =COUNTIF(B$5:B$54,$I5) -> 0 | K5: =COUNTIF(C$5:C$54,$I5) -> 4 | L5: =COUNTIF(D$5:D$54,$I5) -> 4 | M5: =COUNTIF(E$5:E$54,$I5) -> 4 | N5: =COUNTIF(F$5:F$54,$I5) -> 0 | P5: W | Q5: =J5/J$15 -> 0 | R5: =K5/K$15 -> 0.14285714 | S5: =L5/L$15 -> 0.14285714 | T5: =M5/M$15 -> 0.14285714 | U5: =N5/N$15 -> 0
A6: 2 | B6: H2 | C6: H3 | D6: A | E6: Q | F6: K | I6: S | J6: =COUNTIF(B$5:B$54,$I6) -> 1 | K6: =COUNTIF(C$5:C$54,$I6) -> 1 | L6: =COUNTIF(D$5:D$54,$I6) -> 1 | M6: =COUNTIF(E$5:E$54,$I6) -> 1 | N6: =COUNTIF(F$5:F$54,$I6) -> 1 | P6: S | Q6: =J6/J$15 -> 0.041666667 | R6: =K6/K$15 -> 0.035714286 | S6: =L6/L$15 -> 0.035714286 | T6: =M6/M$15 -> 0.035714286 | U6: =N6/N$15 -> 0.041666667
A7: 3 | B7: H3 | C7: H4 | D7: K | E7: J | F7: Q | I7: H1 | J7: =COUNTIF(B$5:B$54,$I7) -> 3 | K7: =COUNTIF(C$5:C$54,$I7) -> 3 | L7: =COUNTIF(D$5:D$54,$I7) -> 3 | M7: =COUNTIF(E$5:E$54,$I7) -> 3 | N7: =COUNTIF(F$5:F$54,$I7) -> 3 | P7: H1 | Q7: =J7/J$15 -> 0.125 | R7: =K7/K$15 -> 0.10714286 | S7: =L7/L$15 -> 0.10714286 | T7: =M7/M$15 -> 0.10714286 | U7: =N7/N$15 -> 0.125
A8: 4 | B8: H4 | C8: A | D8: Q | E8: H1 | F8: J | I8: H2 | J8: =COUNTIF(B$5:B$54,$I8) -> 3 | K8: =COUNTIF(C$5:C$54,$I8) -> 3 | L8: =COUNTIF(D$5:D$54,$I8) -> 3 | M8: =COUNTIF(E$5:E$54,$I8) -> 3 | N8: =COUNTIF(F$5:F$54,$I8) -> 3 | P8: H2 | Q8: =J8/J$15 -> 0.125 | R8: =K8/K$15 -> 0.10714286 | S8: =L8/L$15 -> 0.10714286 | T8: =M8/M$15 -> 0.10714286 | U8: =N8/N$15 -> 0.125
A9: 5 | B9: A | C9: K | D9: S | E9: H2 | F9: H1 | I9: H3 | J9: =COUNTIF(B$5:B$54,$I9) -> 3 | K9: =COUNTIF(C$5:C$54,$I9) -> 3 | L9: =COUNTIF(D$5:D$54,$I9) -> 3 | M9: =COUNTIF(E$5:E$54,$I9) -> 3 | N9: =COUNTIF(F$5:F$54,$I9) -> 3 | P9: H3 | Q9: =J9/J$15 -> 0.125 | R9: =K9/K$15 -> 0.10714286 | S9: =L9/L$15 -> 0.10714286 | T9: =M9/M$15 -> 0.10714286 | U9: =N9/N$15 -> 0.125
A10: 6 | B10: K | C10: Q | D10: H1 | E10: H3 | F10: H2 | I10: H4 | J10: =COUNTIF(B$5:B$54,$I10) -> 3 | K10: =COUNTIF(C$5:C$54,$I10) -> 3 | L10: =COUNTIF(D$5:D$54,$I10) -> 3 | M10: =COUNTIF(E$5:E$54,$I10) -> 3 | N10: =COUNTIF(F$5:F$54,$I10) -> 3 | P10: H4 | Q10: =J10/J$15 -> 0.125 | R10: =K10/K$15 -> 0.10714286 | S10: =L10/L$15 -> 0.10714286 | T10: =M10/M$15 -> 0.10714286 | U10: =N10/N$15 -> 0.125
A11: 7 | B11: Q | C11: J | D11: H2 | E11: H4 | F11: H3 | I11: A | J11: =COUNTIF(B$5:B$54,$I11) -> 3 | K11: =COUNTIF(C$5:C$54,$I11) -> 3 | L11: =COUNTIF(D$5:D$54,$I11) -> 3 | M11: =COUNTIF(E$5:E$54,$I11) -> 3 | N11: =COUNTIF(F$5:F$54,$I11) -> 3 | P11: A | Q11: =J11/J$15 -> 0.125 | R11: =K11/K$15 -> 0.10714286 | S11: =L11/L$15 -> 0.10714286 | T11: =M11/M$15 -> 0.10714286 | U11: =N11/N$15 -> 0.125
A12: 8 | B12: J | C12: W | D12: W | E12: W | F12: H4 | I12: K | J12: =COUNTIF(B$5:B$54,$I12) -> 3 | K12: =COUNTIF(C$5:C$54,$I12) -> 3 | L12: =COUNTIF(D$5:D$54,$I12) -> 3 | M12: =COUNTIF(E$5:E$54,$I12) -> 3 | N12: =COUNTIF(F$5:F$54,$I12) -> 3 | P12: K | Q12: =J12/J$15 -> 0.125 | R12: =K12/K$15 -> 0.10714286 | S12: =L12/L$15 -> 0.10714286 | T12: =M12/M$15 -> 0.10714286 | U12: =N12/N$15 -> 0.125
A13: 9 | B13: H1 | C13: H1 | D13: H3 | E13: A | F13: A | I13: Q | J13: =COUNTIF(B$5:B$54,$I13) -> 3 | K13: =COUNTIF(C$5:C$54,$I13) -> 3 | L13: =COUNTIF(D$5:D$54,$I13) -> 3 | M13: =COUNTIF(E$5:E$54,$I13) -> 3 | N13: =COUNTIF(F$5:F$54,$I13) -> 3 | P13: Q | Q13: =J13/J$15 -> 0.125 | R13: =K13/K$15 -> 0.10714286 | S13: =L13/L$15 -> 0.10714286 | T13: =M13/M$15 -> 0.10714286 | U13: =N13/N$15 -> 0.125
A14: 10 | B14: H2 | C14: H2 | D14: H4 | E14: K | F14: K | I14: J | J14: =COUNTIF(B$5:B$54,$I14) -> 2 | K14: =COUNTIF(C$5:C$54,$I14) -> 2 | L14: =COUNTIF(D$5:D$54,$I14) -> 2 | M14: =COUNTIF(E$5:E$54,$I14) -> 2 | N14: =COUNTIF(F$5:F$54,$I14) -> 2 | P14: J | Q14: =J14/J$15 -> 0.083333333 | R14: =K14/K$15 -> 0.071428571 | S14: =L14/L$15 -> 0.071428571 | T14: =M14/M$15 -> 0.071428571 | U14: =N14/N$15 -> 0.083333333
A15: 11 | B15: H3 | C15: H3 | D15: A | E15: Q | F15: Q | I15: Strip length | J15: =COUNTA(B$5:B$54) -> 24 | K15: =COUNTA(C$5:C$54) -> 28 | L15: =COUNTA(D$5:D$54) -> 28 | M15: =COUNTA(E$5:E$54) -> 28 | N15: =COUNTA(F$5:F$54) -> 24 | P15: check: sums to 1 | Q15: =SUM(Q5:Q14) -> 1 | R15: =SUM(R5:R14) -> 1 | S15: =SUM(S5:S14) -> 1 | T15: =SUM(T5:T14) -> 1 | U15: =SUM(U5:U14) -> 1
A16: 12 | B16: H4 | C16: H4 | D16: K | E16: S | F16: J
A17: 13 | B17: A | C17: A | D17: Q | E17: H1 | F17: H1
A18: 14 | B18: K | C18: K | D18: J | E18: H2 | F18: H2
A19: 15 | B19: Q | C19: W | D19: W | E19: W | F19: H3
A20: 16 | B20: S | C20: Q | D20: H1 | E20: H3 | F20: H4
A21: 17 | B21: H1 | C21: J | D21: H2 | E21: H4 | F21: A
A22: 18 | B22: H2 | C22: H1 | D22: H3 | E22: A | F22: K
A23: 19 | B23: H3 | C23: H2 | D23: H4 | E23: K | F23: Q
A24: 20 | B24: H4 | C24: H3 | D24: A | E24: Q | F24: S
A25: 21 | B25: A | C25: H4 | D25: K | E25: J | F25: H1
A26: 22 | B26: K | C26: W | D26: W | E26: W | F26: H2
A27: 23 | B27: Q | C27: A | D27: Q | E27: H1 | F27: H3
A28: 24 | B28: J | C28: K | D28: J | E28: H2 | F28: H4
A29: 25 | C29: Q | D29: H1 | E29: H3
A30: 26 | C30: S | D30: H2 | E30: H4
A31: 27 | C31: H1 | D31: H3 | E31: A
A32: 28 | C32: H2 | D32: H4 | E32: K
A33: 29
A34: 30
A35: 31
A36: 32
A37: 33
A38: 34
A39: 35
A40: 36
...

Sheet Lines_Base
A1: Kastel Fortune — single-line expected value, base game (exact, closed form)
A3: Base-game strips
A4: P(run >= k) = p1(s) x prod_(i=2..k) [p_i(s) + p_i(W)] — exact because reel 1 carries no wild, so the paying symbol is always the reel-1 symbol. P(run = k) = P(run >= k) - P(run >= k+1).
A5: Symbol | B5: p1(s) | C5: p2(s) | D5: p3(s) | E5: p4(s) | F5: p5(s) | G5: p2(W) | H5: p3(W) | I5: p4(W) | J5: p5(W) | K5: P(run>=1) | L5: P(run>=2) | M5: P(run>=3) | N5: P(run>=4) | O5: P(run>=5) | P5: P(run=3) | Q5: P(run=4) | R5: P(run=5) | S5: pay 3 | T5: pay 4 | U5: pay 5 | V5: E[win] x bet | W5: P(pays)
A6: H1 | B6: =Reels_Base!$Q$7 -> 0.083333333 | C6: =Reels_Base!$R$7 -> 0.11111111 | D6: =Reels_Base!$S$7 -> 0.11111111 | E6: =Reels_Base!$T$7 -> 0.11428571 | F6: =Reels_Base!$U$7 -> 0.088235294 | G6: =Reels_Base!$R$5 -> 0.055555556 | H6: =Reels_Base!$S$5 -> 0.055555556 | I6: =Reels_Base!$T$5 -> 0.057142857 | J6: =Reels_Base!$U$5 -> 0 | K6: =B6 -> 0.083333333 | L6: =K6*(C6+G6) -> 0.013888889 | M6: =L6*(D6+H6) -> 0.0023148148 | N6: =M6*(E6+I6) -> 0.0003968254 | O6: =N6*(F6+J6) -> 3.5014006e-05 | P6: =M6-N6 -> 0.0019179894 | Q6: =N6-O6 -> 0.00036181139 | R6: =O6 -> 3.5014006e-05 | S6: =Paytable!$C$7 -> 2 | T6: =Paytable!$D$7 -> 8 | U6: =Paytable!$E$7 -> 40 | V6: =SUMPRODUCT(P6:R6,S6:U6) -> 0.0081310302 | W6: =SUMPRODUCT(P6:R6,--(S6:U6>0)) -> 0.0023148148
A7: H2 | B7: =Reels_Base!$Q$8 -> 0.11111111 | C7: =Reels_Base!$R$8 -> 0.11111111 | D7: =Reels_Base!$S$8 -> 0.083333333 | E7: =Reels_Base!$T$8 -> 0.057142857 | F7: =Reels_Base!$U$8 -> 0.14705882 | G7: =Reels_Base!$R$5 -> 0.055555556 | H7: =Reels_Base!$S$5 -> 0.055555556 | I7: =Reels_Base!$T$5 -> 0.057142857 | J7: =Reels_Base!$U$5 -> 0 | K7: =B7 -> 0.11111111 | L7: =K7*(C7+G7) -> 0.018518519 | M7: =L7*(D7+H7) -> 0.0025720165 | N7: =M7*(E7+I7) -> 0.00029394474 | O7: =N7*(F7+J7) -> 4.3227167e-05 | P7: =M7-N7 -> 0.0022780717 | Q7: =N7-O7 -> 0.00025071757 | R7: =O7 -> 4.3227167e-05 | S7: =Paytable!$C$8 -> 1.5 | T7: =Paytable!$D$8 -> 5 | U7: =Paytable!$E$8 -> 25 | V7: =SUMPRODUCT(P7:R7,S7:U7) -> 0.0057513746 | W7: =SUMPRODUCT(P7:R7,--(S7:U7>0)) -> 0.0025720165
A8: H3 | B8: =Reels_Base!$Q$9 -> 0.11111111 | C8: =Reels_Base!$R$9 -> 0.083333333 | D8: =Reels_Base!$S$9 -> 0.083333333 | E8: =Reels_Base!$T$9 -> 0.057142857 | F8: =Reels_Base!$U$9 -> 0.11764706 | G8: =Reels_Base!$R$5 -> 0.055555556 | H8: =Reels_Base!$S$5 -> 0.055555556 | I8: =Reels_Base!$T$5 -> 0.057142857 | J8: =Reels_Base!$U$5 -> 0 | K8: =B8 -> 0.11111111 | L8: =K8*(C8+G8) -> 0.015432099 | M8: =L8*(D8+H8) -> 0.0021433471 | N8: =M8*(E8+I8) -> 0.00024495395 | O8: =N8*(F8+J8) -> 2.8818112e-05 | P8: =M8-N8 -> 0.0018983931 | Q8: =N8-O8 -> 0.00021613584 | R8: =O8 -> 2.8818112e-05 | S8: =Paytable!$C$9 -> 1 | T8: =Paytable!$D$9 -> 3 | U8: =Paytable!$E$9 -> 15 | V8: =SUMPRODUCT(P8:R8,S8:U8) -> 0.0029790723 | W8: =SUMPRODUCT(P8:R8,--(S8:U8>0)) -> 0.0021433471
A9: H4 | B9: =Reels_Base!$Q$10 -> 0.11111111 | C9: =Reels_Base!$R$10 -> 0.055555556 | D9: =Reels_Base!$S$10 -> 0.083333333 | E9: =Reels_Base!$T$10 -> 0.14285714 | F9: =Reels_Base!$U$10 -> 0.11764706 | G9: =Reels_Base!$R$5 -> 0.055555556 | H9: =Reels_Base!$S$5 -> 0.055555556 | I9: =Reels_Base!$T$5 -> 0.057142857 | J9: =Reels_Base!$U$5 -> 0 | K9: =B9 -> 0.11111111 | L9: =K9*(C9+G9) -> 0.012345679 | M9: =L9*(D9+H9) -> 0.0017146776 | N9: =M9*(E9+I9) -> 0.00034293553 | O9: =N9*(F9+J9) -> 4.0345356e-05 | P9: =M9-N9 -> 0.0013717421 | Q9: =N9-O9 -> 0.00030259017 | R9: =O9 -> 4.0345356e-05 | S9: =Paytable!$C$10 -> 0.8 | T9: =Paytable!$D$10 -> 2 | U9: =Paytable!$E$10 -> 10 | V9: =SUMPRODUCT(P9:R9,S9:U9) -> 0.0021060276 | W9: =SUMPRODUCT(P9:R9,--(S9:U9>0)) -> 0.0017146776
A10: A | B10: =Reels_Base!$Q$11 -> 0.13888889 | C10: =Reels_Base!$R$11 -> 0.13888889 | D10: =Reels_Base!$S$11 -> 0.13888889 | E10: =Reels_Base!$T$11 -> 0.2 | F10: =Reels_Base!$U$11 -> 0.17647059 | G10: =Reels_Base!$R$5 -> 0.055555556 | H10: =Reels_Base!$S$5 -> 0.055555556 | I10: =Reels_Base!$T$5 -> 0.057142857 | J10: =Reels_Base!$U$5 -> 0 | K10: =B10 -> 0.13888889 | L10: =K10*(C10+G10) -> 0.027006173 | M10: =L10*(D10+H10) -> 0.0052512003 | N10: =M10*(E10+I10) -> 0.0013503086 | O10: =N10*(F10+J10) -> 0.00023828976 | P10: =M10-N10 -> 0.0039008916 | Q10: =N10-O10 -> 0.0011120189 | R10: =O10 -> 0.00023828976 | S10: =Paytable!$C$11 -> 0.4 | T10: =Paytable!$D$11 -> 1.2 | U10: =Paytable!$E$11 -> 5 | V10: =SUMPRODUCT(P10:R10,S10:U10) -> 0.0040862281 | W10: =SUMPRODUCT(P10:R10,--(S10:U10>0)) -> 0.0052512003
A11: K | B11: =Reels_Base!$Q$12 -> 0.13888889 | C11: =Reels_Base!$R$12 -> 0.13888889 | D11: =Reels_Base!$S$12 -> 0.13888889 | E11: =Reels_Base!$T$12 -> 0.085714286 | F11: =Reels_Base!$U$12 -> 0.11764706 | G11: =Reels_Base!$R$5 -> 0.055555556 | H11: =Reels_Base!$S$5 -> 0.055555556 | I11: =Reels_Base!$T$5 -> 0.057142857 | J11: =Reels_Base!$U$5 -> 0 | K11: =B11 -> 0.13888889 | L11: =K11*(C11+G11) -> 0.027006173 | M11: =L11*(D11+H11) -> 0.0052512003 | N11: =M11*(E11+I11) -> 0.00075017147 | O11: =N11*(F11+J11) -> 8.8255467e-05 | P11: =M11-N11 -> 0.0045010288 | Q11: =N11-O11 -> 0.000661916 | R11: =O11 -> 8.8255467e-05 | S11: =Paytable!$C$12 -> 0.3 | T11: =Paytable!$D$12 -> 1 | U11: =Paytable!$E$12 -> 4 | V11: =SUMPRODUCT(P11:R11,S11:U11) -> 0.0023652465 | W11: =SUMPRODUCT(P11:R11,--(S11:U11>0)) -> 0.0052512003
A12: Q | B12: =Reels_Base!$Q$13 -> 0.13888889 | C12: =Reels_Base!$R$13 -> 0.13888889 | D12: =Reels_Base!$S$13 -> 0.13888889 | E12: =Reels_Base!$T$13 -> 0.14285714 | F12: =Reels_Base!$U$13 -> 0.11764706 | G12: =Reels_Base!$R$5 -> 0.055555556 | H12: =Reels_Base!$S$5 -> 0.055555556 | I12: =Reels_Base!$T$5 -> 0.057142857 | J12: =Reels_Base!$U$5 -> 0 | K12: =B12 -> 0.13888889 | L12: =K12*(C12+G12) -> 0.027006173 | M12: =L12*(D12+H12) -> 0.0052512003 | N12: =M12*(E12+I12) -> 0.0010502401 | O12: =N12*(F12+J12) -> 0.00012355765 | P12: =M12-N12 -> 0.0042009602 | Q12: =N12-O12 -> 0.0009266824 | R12: =O12 -> 0.00012355765 | S12: =Paytable!$C$13 -> 0.3 | T12: =Paytable!$D$13 -> 0.8 | U12: =Paytable!$E$13 -> 3 | V12: =SUMPRODUCT(P12:R12,S12:U12) -> 0.0023723069 | W12: =SUMPRODUCT(P12:R12,--(S12:U12>0)) -> 0.0052512003
A13: J | B13: =Reels_Base!$Q$14 -> 0.13888889 | C13: =Reels_Base!$R$14 -> 0.13888889 | D13: =Reels_Base!$S$14 -> 0.13888889 | E13: =Reels_Base!$T$14 -> 0.11428571 | F13: =Reels_Base!$U$14 -> 0.088235294 | G13: =Reels_Base!$R$5 -> 0.055555556 | H13: =Reels_Base!$S$5 -> 0.055555556 | I13: =Reels_Base!$T$5 -> 0.057142857 | J13: =Reels_Base!$U$5 -> 0 | K13: =B13 -> 0.13888889 | L13: =K13*(C13+G13) -> 0.027006173 | M13: =L13*(D13+H13) -> 0.0052512003 | N13: =M13*(E13+I13) -> 0.00090020576 | O13: =N13*(F13+J13) -> 7.942992e-05 | P13: =M13-N13 -> 0.0043509945 | Q13: =N13-O13 -> 0.00082077584 | R13: =O13 -> 7.942992e-05 | S13: =Paytable!$C$14 -> 0.2 | T13: =Paytable!$D$14 -> 0.6 | U13: =Paytable!$E$14 -> 2.5 | V13: =SUMPRODUCT(P13:R13,S13:U13) -> 0.0015612392 | W13: =SUMPRODUCT(P13:R13,--(S13:U13>0)) -> 0.0052512003
A14: TOTAL (one line) | V14: =SUM(V6:V13) -> 0.029352525 | W14: =SUM(W6:W13) -> 0.029749657
A15: Validity check: wild count on reel 1 must be 0 for the closed form | V15: =IF(Reels_Base!$Q$5=0,"OK","INVALID: wild on reel 1") -> OK

Sheet Lines_FS
A1: Kastel Fortune — single-line expected value, free-spin strips (unmultiplied)
A3: Free-spin strips
A4: P(run >= k) = p1(s) x prod_(i=2..k) [p_i(s) + p_i(W)] — exact because reel 1 carries no wild, so the paying symbol is always the reel-1 symbol. P(run = k) = P(run >= k) - P(run >= k+1).
A5: Symbol | B5: p1(s) | C5: p2(s) | D5: p3(s) | E5: p4(s) | F5: p5(s) | G5: p2(W) | H5: p3(W) | I5: p4(W) | J5: p5(W) | K5: P(run>=1) | L5: P(run>=2) | M5: P(run>=3) | N5: P(run>=4) | O5: P(run>=5) | P5: P(run=3) | Q5: P(run=4) | R5: P(run=5) | S5: pay 3 | T5: pay 4 | U5: pay 5 | V5: E[win] x bet | W5: P(pays)
A6: H1 | B6: =Reels_FS!$Q$7 -> 0.125 | C6: =Reels_FS!$R$7 -> 0.10714286 | D6: =Reels_FS!$S$7 -> 0.10714286 | E6: =Reels_FS!$T$7 -> 0.10714286 | F6: =Reels_FS!$U$7 -> 0.125 | G6: =Reels_FS!$R$5 -> 0.14285714 | H6: =Reels_FS!$S$5 -> 0.14285714 | I6: =Reels_FS!$T$5 -> 0.14285714 | J6: =Reels_FS!$U$5 -> 0 | K6: =B6 -> 0.125 | L6: =K6*(C6+G6) -> 0.03125 | M6: =L6*(D6+H6) -> 0.0078125 | N6: =M6*(E6+I6) -> 0.001953125 | O6: =N6*(F6+J6) -> 0.00024414062 | P6: =M6-N6 -> 0.005859375 | Q6: =N6-O6 -> 0.0017089844 | R6: =O6 -> 0.00024414062 | S6: =Paytable!$C$7 -> 2 | T6: =Paytable!$D$7 -> 8 | U6: =Paytable!$E$7 -> 40 | V6: =SUMPRODUCT(P6:R6,S6:U6) -> 0.03515625 | W6: =SUMPRODUCT(P6:R6,--(S6:U6>0)) -> 0.0078125
A7: H2 | B7: =Reels_FS!$Q$8 -> 0.125 | C7: =Reels_FS!$R$8 -> 0.10714286 | D7: =Reels_FS!$S$8 -> 0.10714286 | E7: =Reels_FS!$T$8 -> 0.10714286 | F7: =Reels_FS!$U$8 -> 0.125 | G7: =Reels_FS!$R$5 -> 0.14285714 | H7: =Reels_FS!$S$5 -> 0.14285714 | I7: =Reels_FS!$T$5 -> 0.14285714 | J7: =Reels_FS!$U$5 -> 0 | K7: =B7 -> 0.125 | L7: =K7*(C7+G7) -> 0.03125 | M7: =L7*(D7+H7) -> 0.0078125 | N7: =M7*(E7+I7) -> 0.001953125 | O7: =N7*(F7+J7) -> 0.00024414062 | P7: =M7-N7 -> 0.005859375 | Q7: =N7-O7 -> 0.0017089844 | R7: =O7 -> 0.00024414062 | S7: =Paytable!$C$8 -> 1.5 | T7: =Paytable!$D$8 -> 5 | U7: =Paytable!$E$8 -> 25 | V7: =SUMPRODUCT(P7:R7,S7:U7) -> 0.0234375 | W7: =SUMPRODUCT(P7:R7,--(S7:U7>0)) -> 0.0078125
A8: H3 | B8: =Reels_FS!$Q$9 -> 0.125 | C8: =Reels_FS!$R$9 -> 0.10714286 | D8: =Reels_FS!$S$9 -> 0.10714286 | E8: =Reels_FS!$T$9 -> 0.10714286 | F8: =Reels_FS!$U$9 -> 0.125 | G8: =Reels_FS!$R$5 -> 0.14285714 | H8: =Reels_FS!$S$5 -> 0.14285714 | I8: =Reels_FS!$T$5 -> 0.14285714 | J8: =Reels_FS!$U$5 -> 0 | K8: =B8 -> 0.125 | L8: =K8*(C8+G8) -> 0.03125 | M8: =L8*(D8+H8) -> 0.0078125 | N8: =M8*(E8+I8) -> 0.001953125 | O8: =N8*(F8+J8) -> 0.00024414062 | P8: =M8-N8 -> 0.005859375 | Q8: =N8-O8 -> 0.0017089844 | R8: =O8 -> 0.00024414062 | S8: =Paytable!$C$9 -> 1 | T8: =Paytable!$D$9 -> 3 | U8: =Paytable!$E$9 -> 15 | V8: =SUMPRODUCT(P8:R8,S8:U8) -> 0.014648438 | W8: =SUMPRODUCT(P8:R8,--(S8:U8>0)) -> 0.0078125
A9: H4 | B9: =Reels_FS!$Q$10 -> 0.125 | C9: =Reels_FS!$R$10 -> 0.10714286 | D9: =Reels_FS!$S$10 -> 0.10714286 | E9: =Reels_FS!$T$10 -> 0.10714286 | F9: =Reels_FS!$U$10 -> 0.125 | G9: =Reels_FS!$R$5 -> 0.14285714 | H9: =Reels_FS!$S$5 -> 0.14285714 | I9: =Reels_FS!$T$5 -> 0.14285714 | J9: =Reels_FS!$U$5 -> 0 | K9: =B9 -> 0.125 | L9: =K9*(C9+G9) -> 0.03125 | M9: =L9*(D9+H9) -> 0.0078125 | N9: =M9*(E9+I9) -> 0.001953125 | O9: =N9*(F9+J9) -> 0.00024414062 | P9: =M9-N9 -> 0.005859375 | Q9: =N9-O9 -> 0.0017089844 | R9: =O9 -> 0.00024414062 | S9: =Paytable!$C$10 -> 0.8 | T9: =Paytable!$D$10 -> 2 | U9: =Paytable!$E$10 -> 10 | V9: =SUMPRODUCT(P9:R9,S9:U9) -> 0.010546875 | W9: =SUMPRODUCT(P9:R9,--(S9:U9>0)) -> 0.0078125
A10: A | B10: =Reels_FS!$Q$11 -> 0.125 | C10: =Reels_FS!$R$11 -> 0.10714286 | D10: =Reels_FS!$S$11 -> 0.10714286 | E10: =Reels_FS!$T$11 -> 0.10714286 | F10: =Reels_FS!$U$11 -> 0.125 | G10: =Reels_FS!$R$5 -> 0.14285714 | H10: =Reels_FS!$S$5 -> 0.14285714 | I10: =Reels_FS!$T$5 -> 0.14285714 | J10: =Reels_FS!$U$5 -> 0 | K10: =B10 -> 0.125 | L10: =K10*(C10+G10) -> 0.03125 | M10: =L10*(D10+H10) -> 0.0078125 | N10: =M10*(E10+I10) -> 0.001953125 | O10: =N10*(F10+J10) -> 0.00024414062 | P10: =M10-N10 -> 0.005859375 | Q10: =N10-O10 -> 0.0017089844 | R10: =O10 -> 0.00024414062 | S10: =Paytable!$C$11 -> 0.4 | T10: =Paytable!$D$11 -> 1.2 | U10: =Paytable!$E$11 -> 5 | V10: =SUMPRODUCT(P10:R10,S10:U10) -> 0.0056152344 | W10: =SUMPRODUCT(P10:R10,--(S10:U10>0)) -> 0.0078125
A11: K | B11: =Reels_FS!$Q$12 -> 0.125 | C11: =Reels_FS!$R$12 -> 0.10714286 | D11: =Reels_FS!$S$12 -> 0.10714286 | E11: =Reels_FS!$T$12 -> 0.10714286 | F11: =Reels_FS!$U$12 -> 0.125 | G11: =Reels_FS!$R$5 -> 0.14285714 | H11: =Reels_FS!$S$5 -> 0.14285714 | I11: =Reels_FS!$T$5 -> 0.14285714 | J11: =Reels_FS!$U$5 -> 0 | K11: =B11 -> 0.125 | L11: =K11*(C11+G11) -> 0.03125 | M11: =L11*(D11+H11) -> 0.0078125 | N11: =M11*(E11+I11) -> 0.001953125 | O11: =N11*(F11+J11) -> 0.00024414062 | P11: =M11-N11 -> 0.005859375 | Q11: =N11-O11 -> 0.0017089844 | R11: =O11 -> 0.00024414062 | S11: =Paytable!$C$12 -> 0.3 | T11: =Paytable!$D$12 -> 1 | U11: =Paytable!$E$12 -> 4 | V11: =SUMPRODUCT(P11:R11,S11:U11) -> 0.0044433594 | W11: =SUMPRODUCT(P11:R11,--(S11:U11>0)) -> 0.0078125
A12: Q | B12: =Reels_FS!$Q$13 -> 0.125 | C12: =Reels_FS!$R$13 -> 0.10714286 | D12: =Reels_FS!$S$13 -> 0.10714286 | E12: =Reels_FS!$T$13 -> 0.10714286 | F12: =Reels_FS!$U$13 -> 0.125 | G12: =Reels_FS!$R$5 -> 0.14285714 | H12: =Reels_FS!$S$5 -> 0.14285714 | I12: =Reels_FS!$T$5 -> 0.14285714 | J12: =Reels_FS!$U$5 -> 0 | K12: =B12 -> 0.125 | L12: =K12*(C12+G12) -> 0.03125 | M12: =L12*(D12+H12) -> 0.0078125 | N12: =M12*(E12+I12) -> 0.001953125 | O12: =N12*(F12+J12) -> 0.00024414062 | P12: =M12-N12 -> 0.005859375 | Q12: =N12-O12 -> 0.0017089844 | R12: =O12 -> 0.00024414062 | S12: =Paytable!$C$13 -> 0.3 | T12: =Paytable!$D$13 -> 0.8 | U12: =Paytable!$E$13 -> 3 | V12: =SUMPRODUCT(P12:R12,S12:U12) -> 0.0038574219 | W12: =SUMPRODUCT(P12:R12,--(S12:U12>0)) -> 0.0078125
A13: J | B13: =Reels_FS!$Q$14 -> 0.083333333 | C13: =Reels_FS!$R$14 -> 0.071428571 | D13: =Reels_FS!$S$14 -> 0.071428571 | E13: =Reels_FS!$T$14 -> 0.071428571 | F13: =Reels_FS!$U$14 -> 0.083333333 | G13: =Reels_FS!$R$5 -> 0.14285714 | H13: =Reels_FS!$S$5 -> 0.14285714 | I13: =Reels_FS!$T$5 -> 0.14285714 | J13: =Reels_FS!$U$5 -> 0 | K13: =B13 -> 0.083333333 | L13: =K13*(C13+G13) -> 0.017857143 | M13: =L13*(D13+H13) -> 0.0038265306 | N13: =M13*(E13+I13) -> 0.00081997085 | O13: =N13*(F13+J13) -> 6.8330904e-05 | P13: =M13-N13 -> 0.0030065598 | Q13: =N13-O13 -> 0.00075163994 | R13: =O13 -> 6.8330904e-05 | S13: =Paytable!$C$14 -> 0.2 | T13: =Paytable!$D$14 -> 0.6 | U13: =Paytable!$E$14 -> 2.5 | V13: =SUMPRODUCT(P13:R13,S13:U13) -> 0.0012231232 | W13: =SUMPRODUCT(P13:R13,--(S13:U13>0)) -> 0.0038265306
A14: TOTAL (one line) | V14: =SUM(V6:V13) -> 0.098928201 | W14: =SUM(W6:W13) -> 0.058514031
A15: Validity check: wild count on reel 1 must be 0 for the closed form | V15: =IF(Reels_FS!$Q$5=0,"OK","INVALID: wild on reel 1") -> OK

Sheet Scatters
A1: Kastel Fortune — scatter-count distribution (exact)
A2: Each strip carries exactly one scatter, so P(scatter visible on reel i) = rows x count / length exactly (the 3 stops that show it). The total count is a sum of independent Bernoullis — computed by the DP P_i(k) = P_(i-1)(k)(1-p_i) + P_(i-1)(k-1) p_i.
A4: Base game
A5: Reel | B5: S count | C5: Length | D5: p_i = rows x count / length | E5: P(k=0) | F5: P(k=1) | G5: P(k=2) | H5: P(k=3) | I5: P(k=4) | J5: P(k=5)
A6: 0 | E6: 1 | F6: 0 | G6: 0 | H6: 0 | I6: 0 | J6: 0
A7: 1 | B7: =Reels_Base!$J$6 -> 1 | C7: =Reels_Base!$J$15 -> 36 | D7: =Paytable!$B$26*B7/C7 -> 0.083333333 | E7: =E6*(1-$D7) -> 0.91666667 | F7: =F6*(1-$D7)+E6*$D7 -> 0.083333333 | G7: =G6*(1-$D7)+F6*$D7 -> 0 | H7: =H6*(1-$D7)+G6*$D7 -> 0 | I7: =I6*(1-$D7)+H6*$D7 -> 0 | J7: =J6*(1-$D7)+I6*$D7 -> 0
A8: 2 | B8: =Reels_Base!$K$6 -> 1 | C8: =Reels_Base!$K$15 -> 36 | D8: =Paytable!$B$26*B8/C8 -> 0.083333333 | E8: =E7*(1-$D8) -> 0.84027778 | F8: =F7*(1-$D8)+E7*$D8 -> 0.15277778 | G8: =G7*(1-$D8)+F7*$D8 -> 0.0069444444 | H8: =H7*(1-$D8)+G7*$D8 -> 0 | I8: =I7*(1-$D8)+H7*$D8 -> 0 | J8: =J7*(1-$D8)+I7*$D8 -> 0
A9: 3 | B9: =Reels_Base!$L$6 -> 1 | C9: =Reels_Base!$L$15 -> 36 | D9: =Paytable!$B$26*B9/C9 -> 0.083333333 | E9: =E8*(1-$D9) -> 0.77025463 | F9: =F8*(1-$D9)+E8*$D9 -> 0.21006944 | G9: =G8*(1-$D9)+F8*$D9 -> 0.019097222 | H9: =H8*(1-$D9)+G8*$D9 -> 0.0005787037 | I9: =I8*(1-$D9)+H8*$D9 -> 0 | J9: =J8*(1-$D9)+I8*$D9 -> 0
A10: 4 | B10: =Reels_Base!$M$6 -> 1 | C10: =Reels_Base!$M$15 -> 35 | D10: =Paytable!$B$26*B10/C10 -> 0.085714286 | E10: =E9*(1-$D10) -> 0.7042328 | F10: =F9*(1-$D10)+E9*$D10 -> 0.25808532 | G10: =G9*(1-$D10)+F9*$D10 -> 0.03546627 | H10: =H9*(1-$D10)+G9*$D10 -> 0.0021660053 | I10: =I9*(1-$D10)+H9*$D10 -> 4.9603175e-05 | J10: =J9*(1-$D10)+I9*$D10 -> 0
A11: 5 | B11: =Reels_Base!$N$6 -> 1 | C11: =Reels_Base!$N$15 -> 34 | D11: =Paytable!$B$26*B11/C11 -> 0.088235294 | E11: =E10*(1-$D11) -> 0.64209462 | F11: =F10*(1-$D11)+E10*$D11 -> 0.29745127 | G11: =G10*(1-$D11)+F10*$D11 -> 0.055109127 | H11: =H10*(1-$D11)+G10*$D11 -> 0.0051042639 | I11: =I10*(1-$D11)+H10*$D11 -> 0.00023634454 | J11: =J10*(1-$D11)+I10*$D11 -> 4.3767507e-06
A12: check: sums to 1 | E12: =SUM(E11:J11) -> 1
A14: Base-game scatter pays and trigger
A15: Scatters | B15: P(k) | C15: 1 in | D15: Pay (x bet) | E15: RTP share | F15: Free spins
A16: 3 | B16: =Scatters!$H$11 -> 0.0051042639 | C16: =1/B16 -> 195.91463 | D16: =Paytable!$B$19 -> 2 | E16: =B16*D16 -> 0.010208528 | F16: =Paytable!$C$19 -> 10
A17: 4 | B17: =Scatters!$I$11 -> 0.00023634454 | C17: =1/B17 -> 4231.1111 | D17: =Paytable!$B$20 -> 10 | E17: =B17*D17 -> 0.0023634454 | F17: =Paytable!$C$20 -> 15
A18: 5 | B18: =Scatters!$J$11 -> 4.3767507e-06 | C18: =1/B18 -> 228480 | D18: =Paytable!$B$21 -> 50 | E18: =B18*D18 -> 0.00021883754 | F18: =Paytable!$C$21 -> 20
A19: P(trigger) = P(3+) | B19: =SUM(B16:B18) -> 0.0053449852 | C19: =1/B19 -> 187.09126
A20: Scatter RTP | E20: =SUM(E16:E18) -> 0.012790811
A23: Free spins (retrigger probability per free spin)
A24: Reel | B24: S count | C24: Length | D24: p_i = rows x count / length | E24: P(k=0) | F24: P(k=1) | G24: P(k=2) | H24: P(k=3) | I24: P(k=4) | J24: P(k=5)
A25: 0 | E25: 1 | F25: 0 | G25: 0 | H25: 0 | I25: 0 | J25: 0
A26: 1 | B26: =Reels_FS!$J$6 -> 1 | C26: =Reels_FS!$J$15 -> 24 | D26: =Paytable!$B$26*B26/C26 -> 0.125 | E26: =E25*(1-$D26) -> 0.875 | F26: =F25*(1-$D26)+E25*$D26 -> 0.125 | G26: =G25*(1-$D26)+F25*$D26 -> 0 | H26: =H25*(1-$D26)+G25*$D26 -> 0 | I26: =I25*(1-$D26)+H25*$D26 -> 0 | J26: =J25*(1-$D26)+I25*$D26 -> 0
A27: 2 | B27: =Reels_FS!$K$6 -> 1 | C27: =Reels_FS!$K$15 -> 28 | D27: =Paytable!$B$26*B27/C27 -> 0.10714286 | E27: =E26*(1-$D27) -> 0.78125 | F27: =F26*(1-$D27)+E26*$D27 -> 0.20535714 | G27: =G26*(1-$D27)+F26*$D27 -> 0.013392857 | H27: =H26*(1-$D27)+G26*$D27 -> 0 | I27: =I26*(1-$D27)+H26*$D27 -> 0 | J27: =J26*(1-$D27)+I26*$D27 -> 0
A28: 3 | B28: =Reels_FS!$L$6 -> 1 | C28: =Reels_FS!$L$15 -> 28 | D28: =Paytable!$B$26*B28/C28 -> 0.10714286 | E28: =E27*(1-$D28) -> 0.69754464 | F28: =F27*(1-$D28)+E27*$D28 -> 0.26705995 | G28: =G27*(1-$D28)+F27*$D28 -> 0.033960459 | H28: =H27*(1-$D28)+G27*$D28 -> 0.001434949 | I28: =I27*(1-$D28)+H27*$D28 -> 0 | J28: =J27*(1-$D28)+I27*$D28 -> 0
A29: 4 | B29: =Reels_FS!$M$6 -> 1 | C29: =Reels_FS!$M$15 -> 28 | D29: =Paytable!$B$26*B29/C29 -> 0.10714286 | E29: =E28*(1-$D29) -> 0.62280772 | F29: =F28*(1-$D29)+E28*$D29 -> 0.31318331 | G29: =G28*(1-$D29)+F28*$D29 -> 0.058935405 | H29: =H28*(1-$D29)+G28*$D29 -> 0.0049198251 | I29: =I28*(1-$D29)+H28*$D29 -> 0.00015374453 | J29: =J28*(1-$D29)+I28*$D29 -> 0
A30: 5 | B30: =Reels_FS!$N$6 -> 1 | C30: =Reels_FS!$N$15 -> 24 | D30: =Paytable!$B$26*B30/C30 -> 0.125 | E30: =E29*(1-$D30) -> 0.54495675 | F30: =F29*(1-$D30)+E29*$D30 -> 0.35188636 | G30: =G29*(1-$D30)+F29*$D30 -> 0.090716393 | H30: =H29*(1-$D30)+G29*$D30 -> 0.011671773 | I30: =I29*(1-$D30)+H29*$D30 -> 0.0007495046 | J30: =J29*(1-$D30)+I29*$D30 -> 1.9218067e-05
A31: check: sums to 1 | E31: =SUM(E30:J30) -> 1
A33: P(retrigger per free spin) = P(3+) | B33: =Scatters!$H$30+Scatters!$I$30+Scatters!$J$30 -> 0.012440495

Sheet FreeSpins
A1: Kastel Fortune — free spins as an absorbing Markov chain (expected payout, exact)
A2: State = (spins left n, multiplier m, retriggers used r). E(n,m,r) = m*(mu_wr+mu_wn) + p_wn*E(n-1,m',r) + p_nn*E(n-1,m,r) + p_wr*E(n+4,m',r+1) + p_nr*E(n+4,m,r+1); m' = min(m+1,5); when r = 4 the retrigger branches go to (n-1, ., 4). E(0,.,.) = 0.
A3: Per-free-spin outcome classes (joint law of 'line win > 0' and '3+ scatters'); the four probabilities and two means come from the full enumeration of the free-spin strips (slotmath/exact.py: 12,644,352 combinations). Cross-checks against this workbook's own closed forms are below.
A5: Class | B5: Probability | C5: E[line win x 1{class}] (unmultiplied) | D5: Source
A6: win & retrigger | B6: 0.0047973989 | C6: 0.020220839 | D6: full enumeration (results/kastel_exact.pkl)
A7: win & no retrigger | B7: 0.47059588 | C7: 1.9583432 | D7: full enumeration (results/kastel_exact.pkl)
A8: no win & retrigger | B8: 0.0076430963 | C8: 0 | D8: full enumeration (results/kastel_exact.pkl)
A9: no win & no retrigger | B9: 0.51696362 | C9: 0 | D9: full enumeration (results/kastel_exact.pkl)
A10: check: probabilities sum to 1 | B10: =SUM(B6:B9) -> 1
A11: check: P(retrigger) vs Scatters sheet (closed form) | B11: =B6+B8 -> 0.012440495 | C11: =Scatters!$B$33 -> 0.012440495 | D11: =IF(ABS(B11-C11)<0.000000001,"OK","MISMATCH") -> OK
A12: check: E[line win per free spin] vs Lines_FS (closed form) x lines | B12: =C6+C7 -> 1.978564 | C12: =Paytable!$B$27*Lines_FS!$V$14 -> 1.978564 | D12: =IF(ABS(B12-C12)<0.000000001,"OK","MISMATCH") -> OK
A13: E(n, m, r): expected remaining payout (x bet) from a state. Grid laid out for +5 spins per retrigger, max 4 retriggers, multiplier 1..5 step 1.
A14: m → | B14: 1 | C14: 1 | D14: 1 | E14: 1 | F14: 1 | G14: 2 | H14: 2 | I14: 2 | J14: 2 | K14: 2 | L14: 3 | M14: 3 | N14: 3 | O14: 3 | P14: 3 | Q14: 4 | R14: 4 | S14: 4 | T14: 4 | U14: 4 | V14: 5 | W14: 5 | X14: 5 | Y14: 5 | Z14: 5
A15: r → | B15: 0 | C15: 1 | D15: 2 | E15: 3 | F15: 4 | G15: 0 | H15: 1 | I15: 2 | J15: 3 | K15: 4 | L15: 0 | M15: 1 | N15: 2 | O15: 3 | P15: 4 | Q15: 0 | R15: 1 | S15: 2 | T15: 3 | U15: 4 | V15: 0 | W15: 1 | X15: 2 | Y15: 3 | Z15: 4
A16: n = 0 | B16: 0 | C16: 0 | D16: 0 | E16: 0 | F16: 0 | G16: 0 | H16: 0 | I16: 0 | J16: 0 | K16: 0 | L16: 0 | M16: 0 | N16: 0 | O16: 0 | P16: 0 | Q16: 0 | R16: 0 | S16: 0 | T16: 0 | U16: 0 | V16: 0 | W16: 0 | X16: 0 | Y16: 0 | Z16: 0
A17: 1 | B17: =1*($C$6+$C$7)+$B$7*G16+$B$9*B16+$B$6*H21+$B$8*C21 -> 2.3002244 | C17: =1*($C$6+$C$7)+$B$7*H16+$B$9*C16+$B$6*I21+$B$8*D21 -> 2.2999202 | D17: =1*($C$6+$C$7)+$B$7*I16+$B$9*D16+$B$6*J21+$B$8*E21 -> 2.2968676 | E17: =1*($C$6+$C$7)+$B$7*J16+$B$9*E16+$B$6*K21+$B$8*F21 -> 2.2656254 | F17: =1*($C$6+$C$7)+$B$7*K16+$B$9*F16+$B$6*K16+$B$8*F16 -> 1.978564 | G17: =2*($C$6+$C$7)+$B$7*L16+$B$9*G16+$B$6*M21+$B$8*H21 -> 4.4011312 | H17: =2*($C$6+$C$7)+$B$7*M16+$B$9*H16+$B$6*N21+$B$8*I21 -> 4.4008262 | I17: =2*($C$6+$C$7)+$B$7*N16+$B$9*I16+$B$6*O21+$B$8*J21 -> 4.3977113 | J17: =2*($C$6+$C$7)+$B$7*O16+$B$9*J16+$B$6*P21+$B$8*K21 -> 4.3628441 | K17: =2*($C$6+$C$7)+$B$7*P16+$B$9*K16+$B$6*P16+$B$8*K16 -> 3.9571281 | L17: =3*($C$6+$C$7)+$B$7*Q16+$B$9*L16+$B$6*R21+$B$8*M21 -> 6.486079 | M17: =3*($C$6+$C$7)+$B$7*R16+$B$9*M16+$B$6*S21+$B$8*N21 -> 6.4857738 | N17: =3*($C$6+$C$7)+$B$7*S16+$B$9*N16+$B$6*T21+$B$8*O21 -> 6.4826399 | O17: =3*($C$6+$C$7)+$B$7*T16+$B$9*O16+$B$6*U21+$B$8*P21 -> 6.4459651 | P17: =3*($C$6+$C$7)+$B$7*U16+$B$9*P16+$B$6*U16+$B$8*P16 -> 5.9356921 | Q17: =4*($C$6+$C$7)+$B$7*V16+$B$9*Q16+$B$6*W21+$B$8*R21 -> 8.5397608 | R17: =4*($C$6+$C$7)+$B$7*W16+$B$9*R16+$B$6*X21+$B$8*S21 -> 8.5394556 | S17: =4*($C$6+$C$7)+$B$7*X16+$B$9*S16+$B$6*Y21+$B$8*T21 -> 8.5363181 | T17: =4*($C$6+$C$7)+$B$7*Y16+$B$9*T16+$B$6*Z21+$B$8*U21 -> 8.4990678 | U17: =4*($C$6+$C$7)+$B$7*Z16+$B$9*U16+$B$6*Z16+$B$8*U16 -> 7.9142561 | V17: =5*($C$6+$C$7)+$B$7*V16+$B$9*V16+$B$6*W21+$B$8*W21 -> 10.548957 | W17: =5*($C$6+$C$7)+$B$7*W16+$B$9*W16+$B$6*X21+$B$8*X21 -> 10.548652 | X17: =5*($C$6+$C$7)+$B$7*X16+$B$9*X16+$B$6*Y21+$B$8*Y21 -> 10.545514 | Y17: =5*($C$6+$C$7)+$B$7*Y16+$B$9*Y16+$B$6*Z21+$B$8*Z21 -> 10.508178 | Z17: =5*($C$6+$C$7)+$B$7*Z16+$B$9*Z16+$B$6*Z16+$B$8*Z16 -> 9.8928201
A18: 2 | B18: =1*($C$6+$C$7)+$B$7*G17+$B$9*B17+$B$6*H22+$B$8*C22 -> 5.6600737 | C18: =1*($C$6+$C$7)+$B$7*H17+$B$9*C17+$B$6*I22+$B$8*D22 -> 5.6593708 | D18: =1*($C$6+$C$7)+$B$7*I17+$B$9*D17+$B$6*J22+$B$8*E22 -> 5.6523981 | E18: =1*($C$6+$C$7)+$B$7*J17+$B$9*E17+$B$6*K22+$B$8*F22 -> 5.5805217 | F18: =1*($C$6+$C$7)+$B$7*K17+$B$9*F17+$B$6*K17+$B$8*F17 -> 4.8977241 | G18: =2*($C$6+$C$7)+$B$7*L17+$B$9*G17+$B$6*M22+$B$8*H22 -> 9.8458104 | H18: =2*($C$6+$C$7)+$B$7*M17+$B$9*H17+$B$6*N22+$B$8*I22 -> 9.8451063 | I18: =2*($C$6+$C$7)+$B$7*N17+$B$9*I17+$B$6*O22+$B$8*J22 -> 9.8380394 | J18: =2*($C$6+$C$7)+$B$7*O17+$B$9*J17+$B$6*P22+$B$8*K22 -> 9.7601466 | K18: =2*($C$6+$C$7)+$B$7*P17+$B$9*K17+$B$6*P17+$B$8*K17 -> 8.8548522 | L18: =3*($C$6+$C$7)+$B$7*Q17+$B$9*L17+$B$6*R22+$B$8*M22 -> 13.985043 | M18: =3*($C$6+$C$7)+$B$7*R17+$B$9*M17+$B$6*S22+$B$8*N22 -> 13.984339 | N18: =3*($C$6+$C$7)+$B$7*S17+$B$9*N17+$B$6*T22+$B$8*O22 -> 13.977245 | O18: =3*($C$6+$C$7)+$B$7*T17+$B$9*O17+$B$6*U22+$B$8*P22 -> 13.896691 | P18: =3*($C$6+$C$7)+$B$7*U17+$B$9*P17+$B$6*U17+$B$8*P17 -> 12.81198 | Q18: =4*($C$6+$C$7)+$B$7*V17+$B$9*Q17+$B$6*W22+$B$8*R22 -> 18.049456 | R18: =4*($C$6+$C$7)+$B$7*W17+$B$9*R17+$B$6*X22+$B$8*S22 -> 18.048751 | S18: =4*($C$6+$C$7)+$B$7*X17+$B$9*S17+$B$6*Y22+$B$8*T22 -> 18.041653 | T18: =4*($C$6+$C$7)+$B$7*Y17+$B$9*T17+$B$6*Z22+$B$8*U22 -> 17.960353 | U18: =4*($C$6+$C$7)+$B$7*Z17+$B$9*U17+$B$6*Z17+$B$8*U17 -> 16.769108 | V18: =5*($C$6+$C$7)+$B$7*V17+$B$9*V17+$B$6*W22+$B$8*W22 -> 21.097902 | W18: =5*($C$6+$C$7)+$B$7*W17+$B$9*W17+$B$6*X22+$B$8*X22 -> 21.097198 | X18: =5*($C$6+$C$7)+$B$7*X17+$B$9*X17+$B$6*Y22+$B$8*Y22 -> 21.0901 | Y18: =5*($C$6+$C$7)+$B$7*Y17+$B$9*Y17+$B$6*Z22+$B$8*Z22 -> 21.008701 | Z18: =5*($C$6+$C$7)+$B$7*Z17+$B$9*Z17+$B$6*Z17+$B$8*Z17 -> 19.78564
A19: 3 | B19: =1*($C$6+$C$7)+$B$7*G18+$B$9*B18+$B$6*H23+$B$8*C23 -> 10.067415 | C19: =1*($C$6+$C$7)+$B$7*H18+$B$9*C18+$B$6*I23+$B$8*D23 -> 10.066206 | D19: =1*($C$6+$C$7)+$B$7*I18+$B$9*D18+$B$6*J23+$B$8*E23 -> 10.054398 | E19: =1*($C$6+$C$7)+$B$7*J18+$B$9*E18+$B$6*K23+$B$8*F23 -> 9.9331801 | F19: =1*($C$6+$C$7)+$B$7*K18+$B$9*F18+$B$6*K18+$B$8*F18 -> 8.7574802 | G19: =2*($C$6+$C$7)+$B$7*L18+$B$9*G18+$B$6*M23+$B$8*H23 -> 16.311487 | H19: =2*($C$6+$C$7)+$B$7*M18+$B$9*H18+$B$6*N23+$B$8*I23 -> 16.310277 | I19: =2*($C$6+$C$7)+$B$7*N18+$B$9*I18+$B$6*O23+$B$8*J23 -> 16.298364 | J19: =2*($C$6+$C$7)+$B$7*O18+$B$9*J18+$B$6*P23+$B$8*K23 -> 16.16998 | K19: =2*($C$6+$C$7)+$B$7*P18+$B$9*K18+$B$6*P18+$B$8*K18 -> 14.693172 | L19: =3*($C$6+$C$7)+$B$7*Q18+$B$9*L18+$B$6*R23+$B$8*M23 -> 22.465788 | M19: =3*($C$6+$C$7)+$B$7*R18+$B$9*M18+$B$6*S23+$B$8*N23 -> 22.464578 | N19: =3*($C$6+$C$7)+$B$7*S18+$B$9*N18+$B$6*T23+$B$8*O23 -> 22.452638 | O19: =3*($C$6+$C$7)+$B$7*T18+$B$9*O18+$B$6*U23+$B$8*P23 -> 22.321416 | P19: =3*($C$6+$C$7)+$B$7*U18+$B$9*P18+$B$6*U18+$B$8*P18 -> 20.628864 | Q19: =4*($C$6+$C$7)+$B$7*V18+$B$9*Q18+$B$6*W23+$B$8*R23 -> 28.060838 | R19: =4*($C$6+$C$7)+$B$7*W18+$B$9*R18+$B$6*X23+$B$8*S23 -> 28.059628 | S19: =4*($C$6+$C$7)+$B$7*X18+$B$9*S18+$B$6*Y23+$B$8*T23 -> 28.047683 | T19: =4*($C$6+$C$7)+$B$7*Y18+$B$9*T18+$B$6*Z23+$B$8*U23 -> 27.915752 | U19: =4*($C$6+$C$7)+$B$7*Z18+$B$9*U18+$B$6*Z18+$B$8*U18 -> 26.117403 | V19: =5*($C$6+$C$7)+$B$7*V18+$B$9*V18+$B$6*W23+$B$8*W23 -> 31.646833 | W19: =5*($C$6+$C$7)+$B$7*W18+$B$9*W18+$B$6*X23+$B$8*X23 -> 31.645623 | X19: =5*($C$6+$C$7)+$B$7*X18+$B$9*X18+$B$6*Y23+$B$8*Y23 -> 31.633678 | Y19: =5*($C$6+$C$7)+$B$7*Y18+$B$9*Y18+$B$6*Z23+$B$8*Z23 -> 31.501663 | Z19: =5*($C$6+$C$7)+$B$7*Z18+$B$9*Z18+$B$6*Z18+$B$8*Z18 -> 29.67846
A20: 4 | B20: =1*($C$6+$C$7)+$B$7*G19+$B$9*B19+$B$6*H24+$B$8*C24 -> 15.503506 | C20: =1*($C$6+$C$7)+$B$7*H19+$B$9*C19+$B$6*I24+$B$8*D24 -> 15.501672 | D20: =1*($C$6+$C$7)+$B$7*I19+$B$9*D19+$B$6*J24+$B$8*E24 -> 15.484063 | E20: =1*($C$6+$C$7)+$B$7*J19+$B$9*E19+$B$6*K24+$B$8*F24 -> 15.305622 | F20: =1*($C$6+$C$7)+$B$7*K19+$B$9*F19+$B$6*K19+$B$8*F19 -> 13.557832 | G20: =2*($C$6+$C$7)+$B$7*L19+$B$9*G19+$B$6*M24+$B$8*H24 -> 23.770327 | H20: =2*($C$6+$C$7)+$B$7*M19+$B$9*H19+$B$6*N24+$B$8*I24 -> 23.768491 | I20: =2*($C$6+$C$7)+$B$7*N19+$B$9*I19+$B$6*O24+$B$8*J24 -> 23.750782 | J20: =2*($C$6+$C$7)+$B$7*O19+$B$9*J19+$B$6*P24+$B$8*K24 -> 23.565032 | K20: =2*($C$6+$C$7)+$B$7*P19+$B$9*K19+$B$6*P19+$B$8*K19 -> 21.472088 | L20: =3*($C$6+$C$7)+$B$7*Q19+$B$9*L19+$B$6*R24+$B$8*M24 -> 31.691182 | M20: =3*($C$6+$C$7)+$B$7*R19+$B$9*M19+$B$6*S24+$B$8*N24 -> 31.689346 | N20: =3*($C$6+$C$7)+$B$7*S19+$B$9*N19+$B$6*T24+$B$8*O24 -> 31.671613 | O20: =3*($C$6+$C$7)+$B$7*T19+$B$9*O19+$B$6*U24+$B$8*P24 -> 31.483251 | P20: =3*($C$6+$C$7)+$B$7*U19+$B$9*P19+$B$6*U19+$B$8*P19 -> 29.173771 | Q20: =4*($C$6+$C$7)+$B$7*V19+$B$9*Q19+$B$6*W24+$B$8*R24 -> 38.331706 | R20: =4*($C$6+$C$7)+$B$7*W19+$B$9*R19+$B$6*X24+$B$8*S24 -> 38.329871 | S20: =4*($C$6+$C$7)+$B$7*X19+$B$9*S19+$B$6*Y24+$B$8*T24 -> 38.312134 | T20: =4*($C$6+$C$7)+$B$7*Y19+$B$9*T19+$B$6*Z24+$B$8*U24 -> 38.123182 | U20: =4*($C$6+$C$7)+$B$7*Z19+$B$9*U19+$B$6*Z19+$B$8*U19 -> 35.724562 | V20: =5*($C$6+$C$7)+$B$7*V19+$B$9*V19+$B$6*W24+$B$8*W24 -> 42.195746 | W20: =5*($C$6+$C$7)+$B$7*W19+$B$9*W19+$B$6*X24+$B$8*X24 -> 42.193911 | X20: =5*($C$6+$C$7)+$B$7*X19+$B$9*X19+$B$6*Y24+$B$8*Y24 -> 42.176174 | Y20: =5*($C$6+$C$7)+$B$7*Y19+$B$9*Y19+$B$6*Z24+$B$8*Z24 -> 41.98716 | Z20: =5*($C$6+$C$7)+$B$7*Z19+$B$9*Z19+$B$6*Z19+$B$8*Z19 -> 39.571281
A21: 5 | B21: =1*($C$6+$C$7)+$B$7*G20+$B$9*B20+$B$6*H25+$B$8*C25 -> 21.943868 | C21: =1*($C$6+$C$7)+$B$7*H20+$B$9*C20+$B$6*I25+$B$8*D25 -> 21.941275 | D21: =1*($C$6+$C$7)+$B$7*I20+$B$9*D20+$B$6*J25+$B$8*E25 -> 21.916853 | E21: =1*($C$6+$C$7)+$B$7*J20+$B$9*E20+$B$6*K25+$B$8*F25 -> 21.674088 | F21: =1*($C$6+$C$7)+$B$7*K20+$B$9*F20+$B$6*K20+$B$8*F20 -> 19.298781 | G21: =2*($C$6+$C$7)+$B$7*L20+$B$9*G20+$B$6*M25+$B$8*H25 -> 32.09522 | H21: =2*($C$6+$C$7)+$B$7*M20+$B$9*H20+$B$6*N25+$B$8*I25 -> 32.092626 | I21: =2*($C$6+$C$7)+$B$7*N20+$B$9*I20+$B$6*O25+$B$8*J25 -> 32.068116 | J21: =2*($C$6+$C$7)+$B$7*O20+$B$9*J20+$B$6*P25+$B$8*K25 -> 31.818581 | K21: =2*($C$6+$C$7)+$B$7*P20+$B$9*K20+$B$6*P20+$B$8*K20 -> 29.090545 | L21: =3*($C$6+$C$7)+$B$7*Q20+$B$9*L20+$B$6*R25+$B$8*M25 -> 41.424234 | M21: =3*($C$6+$C$7)+$B$7*R20+$B$9*M20+$B$6*S25+$B$8*N25 -> 41.42164 | N21: =3*($C$6+$C$7)+$B$7*S20+$B$9*N20+$B$6*T25+$B$8*O25 -> 41.39711 | O21: =3*($C$6+$C$7)+$B$7*T20+$B$9*O20+$B$6*U25+$B$8*P25 -> 41.145375 | P21: =3*($C$6+$C$7)+$B$7*U20+$B$9*P20+$B$6*U20+$B$8*P20 -> 38.223665 | Q21: =4*($C$6+$C$7)+$B$7*V20+$B$9*Q20+$B$6*W25+$B$8*R25 -> 48.736782 | R21: =4*($C$6+$C$7)+$B$7*W20+$B$9*R20+$B$6*X25+$B$8*S25 -> 48.734188 | S21: =4*($C$6+$C$7)+$B$7*X20+$B$9*S20+$B$6*Y25+$B$8*T25 -> 48.709655 | T21: =4*($C$6+$C$7)+$B$7*Y20+$B$9*T20+$B$6*Z25+$B$8*U25 -> 48.457469 | U21: =4*($C$6+$C$7)+$B$7*Z20+$B$9*U20+$B$6*Z20+$B$8*U20 -> 45.467522 | V21: =5*($C$6+$C$7)+$B$7*V20+$B$9*V20+$B$6*W25+$B$8*W25 -> 52.744641 | W21: =5*($C$6+$C$7)+$B$7*W20+$B$9*W20+$B$6*X25+$B$8*X25 -> 52.742046 | X21: =5*($C$6+$C$7)+$B$7*X20+$B$9*X20+$B$6*Y25+$B$8*Y25 -> 52.717513 | Y21: =5*($C$6+$C$7)+$B$7*Y20+$B$9*Y20+$B$6*Z25+$B$8*Z25 -> 52.465283 | Z21: =5*($C$6+$C$7)+$B$7*Z20+$B$9*Z20+$B$6*Z20+$B$8*Z20 -> 49.464101
A22: 6 | B22: =1*($C$6+$C$7)+$B$7*G21+$B$9*B21+$B$6*H26+$B$8*C26 -> 29.314623 | C22: =1*($C$6+$C$7)+$B$7*H21+$B$9*C21+$B$6*I26+$B$8*D26 -> 29.311124 | D22: =1*($C$6+$C$7)+$B$7*I21+$B$9*D21+$B$6*J26+$B$8*E26 -> 29.278827 | E22: =1*($C$6+$C$7)+$B$7*J21+$B$9*E21+$B$6*K26+$B$8*F26 -> 28.965283 | F22: =1*($C$6+$C$7)+$B$7*K21+$B$9*F21+$B$6*K21+$B$8*F21 -> 25.932283 | G22: =2*($C$6+$C$7)+$B$7*L21+$B$9*G21+$B$6*M26+$B$8*H26 -> 41.108148 | H22: =2*($C$6+$C$7)+$B$7*M21+$B$9*H21+$B$6*N26+$B$8*I26 -> 41.104649 | I22: =2*($C$6+$C$7)+$B$7*N21+$B$9*I21+$B$6*O26+$B$8*J26 -> 41.072278 | J22: =2*($C$6+$C$7)+$B$7*O21+$B$9*J21+$B$6*P26+$B$8*K26 -> 40.752879 | K22: =2*($C$6+$C$7)+$B$7*P21+$B$9*K21+$B$6*P21+$B$8*K21 -> 37.389497 | L22: =3*($C$6+$C$7)+$B$7*Q21+$B$9*L21+$B$6*R26+$B$8*M26 -> 51.483224 | M22: =3*($C$6+$C$7)+$B$7*R21+$B$9*M21+$B$6*S26+$B$8*N26 -> 51.479724 | N22: =3*($C$6+$C$7)+$B$7*S21+$B$9*N21+$B$6*T26+$B$8*O26 -> 51.447337 | O22: =3*($C$6+$C$7)+$B$7*T21+$B$9*O21+$B$6*U26+$B$8*P26 -> 51.126196 | P22: =3*($C$6+$C$7)+$B$7*U21+$B$9*P21+$B$6*U21+$B$8*P21 -> 47.603038 | Q22: =4*($C$6+$C$7)+$B$7*V21+$B$9*Q21+$B$6*W26+$B$8*R26 -> 59.211265 | R22: =4*($C$6+$C$7)+$B$7*W21+$B$9*R21+$B$6*X26+$B$8*S26 -> 59.207765 | S22: =4*($C$6+$C$7)+$B$7*X21+$B$9*S21+$B$6*Y26+$B$8*T26 -> 59.175377 | T22: =4*($C$6+$C$7)+$B$7*Y21+$B$9*T21+$B$6*Z26+$B$8*U26 -> 58.853907 | U22: =4*($C$6+$C$7)+$B$7*Z21+$B$9*U21+$B$6*Z21+$B$8*U21 -> 55.281725 | V22: =5*($C$6+$C$7)+$B$7*V21+$B$9*V21+$B$6*W26+$B$8*W26 -> 63.293513 | W22: =5*($C$6+$C$7)+$B$7*W21+$B$9*W21+$B$6*X26+$B$8*X26 -> 63.290013 | X22: =5*($C$6+$C$7)+$B$7*X21+$B$9*X21+$B$6*Y26+$B$8*Y26 -> 63.257624 | Y22: =5*($C$6+$C$7)+$B$7*Y21+$B$9*Y21+$B$6*Z26+$B$8*Z26 -> 62.936125 | Z22: =5*($C$6+$C$7)+$B$7*Z21+$B$9*Z21+$B$6*Z21+$B$8*Z21 -> 59.356921
A23: 7 | B23: =1*($C$6+$C$7)+$B$7*G22+$B$9*B22+$B$6*H27+$B$8*C27 -> 37.492705 | C23: =1*($C$6+$C$7)+$B$7*H22+$B$9*C22+$B$6*I27+$B$8*D27 -> 37.488139 | D23: =1*($C$6+$C$7)+$B$7*I22+$B$9*D22+$B$6*J27+$B$8*E27 -> 37.446856 | E23: =1*($C$6+$C$7)+$B$7*J22+$B$9*E22+$B$6*K27+$B$8*F27 -> 37.05657 | F23: =1*($C$6+$C$7)+$B$7*K22+$B$9*F22+$B$6*K22+$B$8*F22 -> 33.35753 | G23: =2*($C$6+$C$7)+$B$7*L22+$B$9*G22+$B$6*M27+$B$8*H27 -> 50.631041 | H23: =2*($C$6+$C$7)+$B$7*M22+$B$9*H22+$B$6*N27+$B$8*I27 -> 50.626474 | I23: =2*($C$6+$C$7)+$B$7*N22+$B$9*I22+$B$6*O27+$B$8*J27 -> 50.585132 | J23: =2*($C$6+$C$7)+$B$7*O22+$B$9*J22+$B$6*P27+$B$8*K27 -> 50.190038 | K23: =2*($C$6+$C$7)+$B$7*P22+$B$9*K22+$B$6*P22+$B$8*K22 -> 46.202074 | L23: =3*($C$6+$C$7)+$B$7*Q22+$B$9*L22+$B$6*R27+$B$8*M27 -> 61.743564 | M23: =3*($C$6+$C$7)+$B$7*R22+$B$9*M22+$B$6*S27+$B$8*N27 -> 61.738997 | N23: =3*($C$6+$C$7)+$B$7*S22+$B$9*N22+$B$6*T27+$B$8*O27 -> 61.697643 | O23: =3*($C$6+$C$7)+$B$7*T22+$B$9*O22+$B$6*U27+$B$8*P27 -> 61.30123 | P23: =3*($C$6+$C$7)+$B$7*U22+$B$9*P22+$B$6*U22+$B$8*P22 -> 57.189126 | Q23: =4*($C$6+$C$7)+$B$7*V22+$B$9*Q22+$B$6*W27+$B$8*R27 -> 69.721634 | R23: =4*($C$6+$C$7)+$B$7*W22+$B$9*R22+$B$6*X27+$B$8*S27 -> 69.717067 | S23: =4*($C$6+$C$7)+$B$7*X22+$B$9*S22+$B$6*Y27+$B$8*T27 -> 69.675712 | T23: =4*($C$6+$C$7)+$B$7*Y22+$B$9*T22+$B$6*Z27+$B$8*U27 -> 69.27907 | U23: =4*($C$6+$C$7)+$B$7*Z22+$B$9*U22+$B$6*Z22+$B$8*U22 -> 65.133302 | V23: =5*($C$6+$C$7)+$B$7*V22+$B$9*V22+$B$6*W27+$B$8*W27 -> 73.842359 | W23: =5*($C$6+$C$7)+$B$7*W22+$B$9*W22+$B$6*X27+$B$8*X27 -> 73.837792 | X23: =5*($C$6+$C$7)+$B$7*X22+$B$9*X22+$B$6*Y27+$B$8*Y27 -> 73.796437 | Y23: =5*($C$6+$C$7)+$B$7*Y22+$B$9*Y22+$B$6*Z27+$B$8*Z27 -> 73.399776 | Z23: =5*($C$6+$C$7)+$B$7*Z22+$B$9*Z22+$B$6*Z22+$B$8*Z22 -> 69.249741
A24: 8 | B24: =1*($C$6+$C$7)+$B$7*G23+$B$9*B23+$B$6*H28+$B$8*C28 -> 46.329879 | C24: =1*($C$6+$C$7)+$B$7*H23+$B$9*C23+$B$6*I28+$B$8*D28 -> 46.324069 | D24: =1*($C$6+$C$7)+$B$7*I23+$B$9*D23+$B$6*J28+$B$8*E28 -> 46.272641 | E24: =1*($C$6+$C$7)+$B$7*J23+$B$9*E23+$B$6*K28+$B$8*F28 -> 45.800001 | F24: =1*($C$6+$C$7)+$B$7*K23+$B$9*F23+$B$6*K23+$B$8*F23 -> 41.442304 | G24: =2*($C$6+$C$7)+$B$7*L23+$B$9*G23+$B$6*M28+$B$8*H28 -> 60.512872 | H24: =2*($C$6+$C$7)+$B$7*M23+$B$9*H23+$B$6*N28+$B$8*I28 -> 60.507061 | I24: =2*($C$6+$C$7)+$B$7*N23+$B$9*I23+$B$6*O28+$B$8*J28 -> 60.455588 | J24: =2*($C$6+$C$7)+$B$7*O23+$B$9*J23+$B$6*P28+$B$8*K28 -> 59.97916 | K24: =2*($C$6+$C$7)+$B$7*P23+$B$9*K23+$B$6*P23+$B$8*K23 -> 55.382373 | L24: =3*($C$6+$C$7)+$B$7*Q23+$B$9*L23+$B$6*R28+$B$8*M28 -> 72.124989 | M24: =3*($C$6+$C$7)+$B$7*R23+$B$9*M23+$B$6*S28+$B$8*N28 -> 72.119178 | N24: =3*($C$6+$C$7)+$B$7*S23+$B$9*N23+$B$6*T28+$B$8*O28 -> 72.067697 | O24: =3*($C$6+$C$7)+$B$7*T23+$B$9*O23+$B$6*U28+$B$8*P28 -> 71.590305 | P24: =3*($C$6+$C$7)+$B$7*U23+$B$9*P23+$B$6*U23+$B$8*P23 -> 66.901426 | Q24: =4*($C$6+$C$7)+$B$7*V23+$B$9*Q23+$B$6*W28+$B$8*R28 -> 80.25055 | R24: =4*($C$6+$C$7)+$B$7*W23+$B$9*R23+$B$6*X28+$B$8*S28 -> 80.244739 | S24: =4*($C$6+$C$7)+$B$7*X23+$B$9*S23+$B$6*Y28+$B$8*T28 -> 80.193257 | T24: =4*($C$6+$C$7)+$B$7*Y23+$B$9*T23+$B$6*Z28+$B$8*U28 -> 79.71571 | U24: =4*($C$6+$C$7)+$B$7*Z23+$B$9*U23+$B$6*Z23+$B$8*U23 -> 75.004485 | V24: =5*($C$6+$C$7)+$B$7*V23+$B$9*V23+$B$6*W28+$B$8*W28 -> 84.391178 | W24: =5*($C$6+$C$7)+$B$7*W23+$B$9*W23+$B$6*X28+$B$8*X28 -> 84.385367 | X24: =5*($C$6+$C$7)+$B$7*X23+$B$9*X23+$B$6*Y28+$B$8*Y28 -> 84.333884 | Y24: =5*($C$6+$C$7)+$B$7*Y23+$B$9*Y23+$B$6*Z28+$B$8*Z28 -> 83.856325 | Z24: =5*($C$6+$C$7)+$B$7*Z23+$B$9*Z23+$B$6*Z23+$B$8*Z23 -> 79.142561
A25: 9 | B25: =1*($C$6+$C$7)+$B$7*G24+$B$9*B24+$B$6*H29+$B$8*C29 -> 55.677857 | C25: =1*($C$6+$C$7)+$B$7*H24+$B$9*C24+$B$6*I29+$B$8*D29 -> 55.670612 | D25: =1*($C$6+$C$7)+$B$7*I24+$B$9*D24+$B$6*J29+$B$8*E29 -> 55.607833 | E25: =1*($C$6+$C$7)+$B$7*J24+$B$9*E24+$B$6*K29+$B$8*F29 -> 55.047475 | F25: =1*($C$6+$C$7)+$B$7*K24+$B$9*F24+$B$6*K24+$B$8*F24 -> 50.047883 | G25: =2*($C$6+$C$7)+$B$7*L24+$B$9*G24+$B$6*M29+$B$8*H29 -> 70.637578 | H25: =2*($C$6+$C$7)+$B$7*M24+$B$9*H24+$B$6*N29+$B$8*I29 -> 70.630333 | I25: =2*($C$6+$C$7)+$B$7*N24+$B$9*I24+$B$6*O29+$B$8*J29 -> 70.56752 | J25: =2*($C$6+$C$7)+$B$7*O24+$B$9*J24+$B$6*P29+$B$8*K29 -> 70.004276 | K25: =2*($C$6+$C$7)+$B$7*P24+$B$9*K24+$B$6*P24+$B$8*K24 -> 64.815581 | L25: =3*($C$6+$C$7)+$B$7*Q24+$B$9*L24+$B$6*R29+$B$8*M29 -> 82.577797 | M25: =3*($C$6+$C$7)+$B$7*R24+$B$9*M24+$B$6*S29+$B$8*N29 -> 82.570552 | N25: =3*($C$6+$C$7)+$B$7*S24+$B$9*N24+$B$6*T29+$B$8*O29 -> 82.507733 | O25: =3*($C$6+$C$7)+$B$7*T24+$B$9*O24+$B$6*U29+$B$8*P29 -> 81.943806 | P25: =3*($C$6+$C$7)+$B$7*U24+$B$9*P24+$B$6*U24+$B$8*P24 -> 76.689258 | Q25: =4*($C$6+$C$7)+$B$7*V24+$B$9*Q24+$B$6*W29+$B$8*R29 -> 90.789043 | R25: =4*($C$6+$C$7)+$B$7*W24+$B$9*R24+$B$6*X29+$B$8*S29 -> 90.781797 | S25: =4*($C$6+$C$7)+$B$7*X24+$B$9*S24+$B$6*Y29+$B$8*T29 -> 90.718977 | T25: =4*($C$6+$C$7)+$B$7*Y24+$B$9*T24+$B$6*Z29+$B$8*U29 -> 90.154947 | U25: =4*($C$6+$C$7)+$B$7*Z24+$B$9*U24+$B$6*Z24+$B$8*U24 -> 84.885955 | V25: =5*($C$6+$C$7)+$B$7*V24+$B$9*V24+$B$6*W29+$B$8*W29 -> 94.939965 | W25: =5*($C$6+$C$7)+$B$7*W24+$B$9*W24+$B$6*X29+$B$8*X29 -> 94.932719 | X25: =5*($C$6+$C$7)+$B$7*X24+$B$9*X24+$B$6*Y29+$B$8*Y29 -> 94.869899 | Y25: =5*($C$6+$C$7)+$B$7*Y24+$B$9*Y24+$B$6*Z29+$B$8*Z29 -> 94.305862 | Z25: =5*($C$6+$C$7)+$B$7*Z24+$B$9*Z24+$B$6*Z24+$B$8*Z24 -> 89.035381
A26: 10 | B26: =1*($C$6+$C$7)+$B$7*G25+$B$9*B25+$B$6*H30+$B$8*C30 -> 65.404958 | C26: =1*($C$6+$C$7)+$B$7*H25+$B$9*C25+$B$6*I30+$B$8*D30 -> 65.396072 | D26: =1*($C$6+$C$7)+$B$7*I25+$B$9*D25+$B$6*J30+$B$8*E30 -> 65.32069 | E26: =1*($C$6+$C$7)+$B$7*J25+$B$9*E25+$B$6*K30+$B$8*F30 -> 64.667425 | F26: =1*($C$6+$C$7)+$B$7*K25+$B$9*F25+$B$6*K25+$B$8*F25 -> 59.046912 | G26: =2*($C$6+$C$7)+$B$7*L25+$B$9*G25+$B$6*M30+$B$8*H30 -> 80.921635 | H26: =2*($C$6+$C$7)+$B$7*M25+$B$9*H25+$B$6*N30+$B$8*I30 -> 80.912748 | I26: =2*($C$6+$C$7)+$B$7*N25+$B$9*I25+$B$6*O30+$B$8*J30 -> 80.837342 | J26: =2*($C$6+$C$7)+$B$7*O25+$B$9*J25+$B$6*P30+$B$8*K30 -> 80.18194 | K26: =2*($C$6+$C$7)+$B$7*P25+$B$9*K25+$B$6*P25+$B$8*K25 -> 74.417376 | L26: =3*($C$6+$C$7)+$B$7*Q25+$B$9*L25+$B$6*R30+$B$8*M30 -> 93.072045 | M26: =3*($C$6+$C$7)+$B$7*R25+$B$9*M25+$B$6*S30+$B$8*N30 -> 93.063158 | N26: =3*($C$6+$C$7)+$B$7*S25+$B$9*N25+$B$6*T30+$B$8*O30 -> 92.987747 | O26: =3*($C$6+$C$7)+$B$7*T25+$B$9*O25+$B$6*U30+$B$8*P30 -> 92.331873 | P26: =3*($C$6+$C$7)+$B$7*U25+$B$9*P25+$B$6*U25+$B$8*P25 -> 86.521605 | Q26: =4*($C$6+$C$7)+$B$7*V25+$B$9*Q25+$B$6*W30+$B$8*R30 -> 101.33247 | R26: =4*($C$6+$C$7)+$B$7*W25+$B$9*R25+$B$6*X30+$B$8*S30 -> 101.32358 | S26: =4*($C$6+$C$7)+$B$7*X25+$B$9*S25+$B$6*Y30+$B$8*T30 -> 101.24817 | T26: =4*($C$6+$C$7)+$B$7*Y25+$B$9*T25+$B$6*Z30+$B$8*U30 -> 100.59223 | U26: =4*($C$6+$C$7)+$B$7*Z25+$B$9*U25+$B$6*Z25+$B$8*U25 -> 94.77282 | V26: =5*($C$6+$C$7)+$B$7*V25+$B$9*V25+$B$6*W30+$B$8*W30 -> 105.48872 | W26: =5*($C$6+$C$7)+$B$7*W25+$B$9*W25+$B$6*X30+$B$8*X30 -> 105.47983 | X26: =5*($C$6+$C$7)+$B$7*X25+$B$9*X25+$B$6*Y30+$B$8*Y30 -> 105.40442 | Y26: =5*($C$6+$C$7)+$B$7*Y25+$B$9*Y25+$B$6*Z30+$B$8*Z30 -> 104.74847 | Z26: =5*($C$6+$C$7)+$B$7*Z25+$B$9*Z25+$B$6*Z25+$B$8*Z25 -> 98.928201
A27: 11 | B27: =1*($C$6+$C$7)+$B$7*G26+$B$9*B26+$B$6*H31+$B$8*C31 -> 75.403529 | C27: =1*($C$6+$C$7)+$B$7*H26+$B$9*C26+$B$6*I31+$B$8*D31 -> 75.39278 | D27: =1*($C$6+$C$7)+$B$7*I26+$B$9*D26+$B$6*J31+$B$8*E31 -> 75.3035 | E27: =1*($C$6+$C$7)+$B$7*J26+$B$9*E26+$B$6*K31+$B$8*F31 -> 74.552275 | F27: =1*($C$6+$C$7)+$B$7*K26+$B$9*F26+$B$6*K26+$B$8*F26 -> 68.332491 | G27: =2*($C$6+$C$7)+$B$7*L26+$B$9*G26+$B$6*M31+$B$8*H31 -> 91.307688 | H27: =2*($C$6+$C$7)+$B$7*M26+$B$9*H26+$B$6*N31+$B$8*I31 -> 91.296939 | I27: =2*($C$6+$C$7)+$B$7*N26+$B$9*I26+$B$6*O31+$B$8*J31 -> 91.207642 | J27: =2*($C$6+$C$7)+$B$7*O26+$B$9*J26+$B$6*P31+$B$8*K31 -> 90.454872 | K27: =2*($C$6+$C$7)+$B$7*P26+$B$9*K26+$B$6*P26+$B$8*K26 -> 84.128773 | L27: =3*($C$6+$C$7)+$B$7*Q26+$B$9*L26+$B$6*R31+$B$8*M31 -> 103.59005 | M27: =3*($C$6+$C$7)+$B$7*R26+$B$9*M26+$B$6*S31+$B$8*N31 -> 103.5793 | N27: =3*($C$6+$C$7)+$B$7*S26+$B$9*N26+$B$6*T31+$B$8*O31 -> 103.49 | O27: =3*($C$6+$C$7)+$B$7*T26+$B$9*O26+$B$6*U31+$B$8*P31 -> 102.73691 | P27: =3*($C$6+$C$7)+$B$7*U26+$B$9*P26+$B$6*U26+$B$8*P26 -> 96.379869 | Q27: =4*($C$6+$C$7)+$B$7*V26+$B$9*Q26+$B$6*W31+$B$8*R31 -> 111.87843 | R27: =4*($C$6+$C$7)+$B$7*W26+$B$9*R26+$B$6*X31+$B$8*S31 -> 111.86768 | S27: =4*($C$6+$C$7)+$B$7*X26+$B$9*S26+$B$6*Y31+$B$8*T31 -> 111.77838 | T27: =4*($C$6+$C$7)+$B$7*Y26+$B$9*T26+$B$6*Z31+$B$8*U31 -> 111.02525 | U27: =4*($C$6+$C$7)+$B$7*Z26+$B$9*U26+$B$6*Z26+$B$8*U26 -> 104.66252 | V27: =5*($C$6+$C$7)+$B$7*V26+$B$9*V26+$B$6*W31+$B$8*W31 -> 116.03743 | W27: =5*($C$6+$C$7)+$B$7*W26+$B$9*W26+$B$6*X31+$B$8*X31 -> 116.02668 | X27: =5*($C$6+$C$7)+$B$7*X26+$B$9*X26+$B$6*Y31+$B$8*Y31 -> 115.93738 | Y27: =5*($C$6+$C$7)+$B$7*Y26+$B$9*Y26+$B$6*Z31+$B$8*Z31 -> 115.18424 | Z27: =5*($C$6+$C$7)+$B$7*Z26+$B$9*Z26+$B$6*Z26+$B$8*Z26 -> 108.82102
